Workbook

Sheet النصاب الكامل
A1: النصاب الكامل | S1: السوابع | AK1: الفعلي | BD1: 1 | BP1: 2 | CB1: 3 | CN1: 4 | CZ1: 5
A2: م | B2: الاسم | C2: 11 | D2: =C2+10 -> 21 | E2: =C2+1 -> 12 | F2: =E2+10 -> 22 | G2: =E2+1 -> 13 | H2: =G2+10 -> 23 | I2: =G2+1 -> 14 | J2: =I2+10 -> 24 | K2: =I2+1 -> 15 | L2: =K2+10 -> 25 | M2: =K2+1 -> 16 | N2: =M2+10 -> 26 | O2: م | P2: ث | S2: م | T2: الاسم | U2: 11 | V2: =U2+10 -> 21 | W2: =U2+1 -> 12 | X2: =W2+10 -> 22 | Y2: =W2+1 -> 13 | Z2: =Y2+10 -> 23 | AA2: =Y2+1 -> 14 | AB2: =AA2+10 -> 24 | AC2: =AA2+1 -> 15 | AD2: =AC2+10 -> 25 | AE2: =AC2+1 -> 16 | AF2: =AE2+10 -> 26 | AG2: م | AH2: ث | AK2: م | AL2: الاسم | AM2: 11 | AN2: =AM2+10 -> 21 | AO2: =AM2+1 -> 12 | AP2: =AO2+10 -> 22 | AQ2: =AO2+1 -> 13 | AR2: =AQ2+10 -> 23 | AS2: =AQ2+1 -> 14 | AT2: =AS2+10 -> 24 | AU2: =AS2+1 -> 15 | AV2: =AU2+10 -> 25 | AW2: =AU2+1 -> 16 | AX2: =AW2+10 -> 26 | AY2: =MAX(AY3:AY31) -> 20 | BB2: م | BC2: الاسم | BD2: 11 | BE2: 21 | BF2: 12 | BG2: 22 | BH2: 13 | BI2: 23 | BJ2: 14 | BK2: 24 | BL2: 15 | BM2: 25 | BN2: 16 | BO2: 26 | BP2: 11 | BQ2: 21 | BR2: 12 | BS2: 22 | BT2: 13 | BU2: 23 | BV2: 14 | BW2: 24 | BX2: 15 | BY2: 25 | BZ2: 16 | CA2: 26 | CB2: 11 | CC2: 21 | CD2: 12 | CE2: 22 | CF2: 13 | CG2: 23 | CH2: 14 | CI2: 24 | CJ2: 15 | CK2: 25 | CL2: 16 | CM2: 26 | CN2: 11 | CO2: 21 | CP2: 12 | CQ2: 22 | CR2: 13 | CS2: 23 | CT2: 14 | CU2: 24 | CV2: 15 | CW2: 25 | CX2: 16 | CY2: 26 | CZ2: 11 | DA2: 21 | DB2: 12 | DC2: 22 | DD2: 13 | DE2: 23 | DF2: 14 | DG2: 24 | DH2: 15 | DI2: 25 | DJ2: 16 | DK2: 26 | DP2: 1 | DQ2: =DP2+1 -> 2 | DR2: =DQ2+1 -> 3 | DS2: =DR2+1 -> 4 | DT2: =DS2+1 -> 5 | DU2: =DT2+1 -> 6 | DV2: =DU2+1 -> 7 | DW2: =DV2+1 -> 8 | DX2: =DW2+1 -> 9 | ... FW2: =FV2+1 -> 60
A3: 1 | B3: علي حسين | G3: 6 | H3: 6 | O3: =SUM(C3:H3) -> 12 | P3: =SUM(I3:N3) -> 0 | Q3: =SUM(C3:N3) -> 12 | S3: 1 | T3: =B3 -> علي حسين | AG3: =SUM(U3:Z3) -> 0 | AH3: =SUM(AA3:AF3) -> 0 | AI3: =AH3+AG3 -> 0 | AJ3: 0 | AK3: 1 | AL3: =B3 -> علي حسين | AM3: =C3-U3 -> 0 | AN3: =D3-V3 -> 0 | AO3: =E3-W3 -> 0 | AP3: =F3-X3 -> 0 | AQ3: =G3-Y3 -> 6 | AR3: =H3-Z3 -> 6 | AS3: =I3-AA3 -> 0 | AT3: =J3-AB3 -> 0 | ... AX3: =N3-AF3 -> 0 | AY3: =SUM(AM3:AX3) -> 12 | AZ3: =AX3*$AX$2+AW3*$AW$2+AV3*$AV$2+AU3*$AU$2+AT3*$AT$2+AS3*$AS$2+AR3*$AR$2+AQ3*$AQ$2+AP3*$AP$2+AO3*$AO$2+AN3*$AN$2+AM3*$AM$2 -> 216 | BB3: 1 | BC3: علي حسين | DL3: =SUM(BD3:DK3) -> 0 | DM3: 2 | DN3: =DM3-DL3 -> 2 | DO3: =SUM(DP3:FW3) -> 0 | DP3: =BD3*11 -> 0 | DQ3: =BE3*21 -> 0 | DR3: =BF3*12 -> 0 | DS3: =BG3*22 -> 0 | DT3: =BH3*13 -> 0 | DU3: =BI3*23 -> 0 | DV3: =BJ3*14 -> 0 | DW3: =BK3*24 -> 0 | DX3: =BL3*15 -> 0 | DY3: =BM3*25 -> 0 | DZ3: =BN3*16 -> 0 | EA3: =BO3*26 -> 0 | EB3: =BP3*11 -> 0 | EC3: =BQ3*21 -> 0 | ED3: =BR3*12 -> 0 | EE3: =BS3*22 -> 0 | EF3: =BT3*13 -> 0 | EG3: =BU3*23 -> 0 | EH3: =BV3*14 -> 0 | EI3: =BW3*24 -> 0 | EJ3: =BX3*15 -> 0 | EK3: =BY3*25 -> 0 | EL3: =BZ3*16 -> 0 | EM3: =CA3*26 -> 0 | EN3: =CB3*11 -> 0 | EO3: =CC3*21 -> 0 | EP3: =CD3*12 -> 0 | EQ3: =CE3*22 -> 0 | ER3: =CF3*13 -> 0 | ES3: =CG3*23 -> 0 | ET3: =CH3*14 -> 0 | EU3: =CI3*24 -> 0 | EV3: =CJ3*15 -> 0 | EW3: =CK3*25 -> 0 | EX3: =CL3*16 -> 0 | EY3: =CM3*26 -> 0 | EZ3: =CN3*11 -> 0 | FA3: =CO3*21 -> 0 | FB3: =CP3*12 -> 0 | FC3: =CQ3*22 -> 0 | FD3: =CR3*13 -> 0 | FE3: =CS3*23 -> 0 | FF3: =CT3*14 -> 0 | FG3: =CU3*24 -> 0 | FH3: =CV3*15 -> 0 | FI3: =CW3*25 -> 0 | FJ3: =CX3*16 -> 0 | FK3: =CY3*26 -> 0 | FL3: =CZ3*11 -> 0 | FM3: =DA3*21 -> 0 | FN3: =DB3*12 -> 0 | FO3: =DC3*22 -> 0 | FP3: =DD3*13 -> 0 | FQ3: =DE3*23 -> 0 | FR3: =DF3*14 -> 0 | FS3: =DG3*24 -> 0 | FT3: =DH3*15 -> 0 | FU3: =DI3*25 -> 0 | FV3: =DJ3*16 -> 0 | FW3: =DK3*26 -> 0 | FX3: =#REF! -> #REF! | FY3: =FX3-DO3 -> #REF!
A4: =A3+1 -> 2 | B4: خالد جابر | C4: 7 | E4: 2 | F4: 2 | O4: =SUM(C4:H4) -> 11 | P4: =SUM(I4:N4) -> 0 | Q4: =SUM(C4:N4) -> 11 | S4: =S3+1 -> 2 | T4: =B4 -> خالد جابر | AG4: =SUM(U4:Z4) -> 0 | AH4: =SUM(AA4:AF4) -> 0 | AI4: =AH4+AG4 -> 0 | AJ4: 5 | AK4: =AK3+1 -> 2 | AL4: =B4 -> خالد جابر | AM4: =C4-U4 -> 7 | AN4: =D4-V4 -> 0 | AO4: =E4-W4 -> 2 | AP4: =F4-X4 -> 2 | AQ4: =G4-Y4 -> 0 | AR4: =H4-Z4 -> 0 | AS4: =I4-AA4 -> 0 | AT4: =J4-AB4 -> 0 | ... AX4: =N4-AF4 -> 0 | AY4: =SUM(AM4:AX4) -> 11 | AZ4: =AX4*$AX$2+AW4*$AW$2+AV4*$AV$2+AU4*$AU$2+AT4*$AT$2+AS4*$AS$2+AR4*$AR$2+AQ4*$AQ$2+AP4*$AP$2+AO4*$AO$2+AN4*$AN$2+AM4*$AM$2 -> 145 | BB4: 2 | BC4: خالد جابر | DL4: =SUM(BD4:DK4) -> 0 | DM4: 17 | DN4: =DM4-DL4 -> 17 | DO4: =SUM(DP4:FW4) -> 0 | DP4: =BD4*11 -> 0 | DQ4: =BE4*21 -> 0 | DR4: =BF4*12 -> 0 | DS4: =BG4*22 -> 0 | DT4: =BH4*13 -> 0 | DU4: =BI4*23 -> 0 | DV4: =BJ4*14 -> 0 | DW4: =BK4*24 -> 0 | DX4: =BL4*15 -> 0 | DY4: =BM4*25 -> 0 | DZ4: =BN4*16 -> 0 | EA4: =BO4*26 -> 0 | EB4: =BP4*11 -> 0 | EC4: =BQ4*21 -> 0 | ED4: =BR4*12 -> 0 | EE4: =BS4*22 -> 0 | EF4: =BT4*13 -> 0 | EG4: =BU4*23 -> 0 | EH4: =BV4*14 -> 0 | EI4: =BW4*24 -> 0 | EJ4: =BX4*15 -> 0 | EK4: =BY4*25 -> 0 | EL4: =BZ4*16 -> 0 | EM4: =CA4*26 -> 0 | EN4: =CB4*11 -> 0 | EO4: =CC4*21 -> 0 | EP4: =CD4*12 -> 0 | EQ4: =CE4*22 -> 0 | ER4: =CF4*13 -> 0 | ES4: =CG4*23 -> 0 | ET4: =CH4*14 -> 0 | EU4: =CI4*24 -> 0 | EV4: =CJ4*15 -> 0 | EW4: =CK4*25 -> 0 | EX4: =CL4*16 -> 0 | EY4: =CM4*26 -> 0 | EZ4: =CN4*11 -> 0 | FA4: =CO4*21 -> 0 | FB4: =CP4*12 -> 0 | FC4: =CQ4*22 -> 0 | FD4: =CR4*13 -> 0 | FE4: =CS4*23 -> 0 | FF4: =CT4*14 -> 0 | FG4: =CU4*24 -> 0 | FH4: =CV4*15 -> 0 | FI4: =CW4*25 -> 0 | FJ4: =CX4*16 -> 0 | FK4: =CY4*26 -> 0 | FL4: =CZ4*11 -> 0 | FM4: =DA4*21 -> 0 | FN4: =DB4*12 -> 0 | FO4: =DC4*22 -> 0 | FP4: =DD4*13 -> 0 | FQ4: =DE4*23 -> 0 | FR4: =DF4*14 -> 0 | FS4: =DG4*24 -> 0 | FT4: =DH4*15 -> 0 | FU4: =DI4*25 -> 0 | FV4: =DJ4*16 -> 0 | FW4: =DK4*26 -> 0 | FX4: =#REF! -> #REF! | FY4: =FX4-DO4 -> #REF!
A5: =A4+1 -> 3 | B5: فرحان علي | E5: 5 | F5: 5 | M5: 2 | N5: 2 | O5: =SUM(C5:H5) -> 10 | P5: =SUM(I5:N5) -> 4 | Q5: =SUM(C5:N5) -> 14 | S5: =S4+1 -> 3 | T5: =B5 -> فرحان علي | AG5: =SUM(U5:Z5) -> 0 | AH5: =SUM(AA5:AF5) -> 0 | AI5: =AH5+AG5 -> 0 | AJ5: 3 | AK5: =AK4+1 -> 3 | AL5: =B5 -> فرحان علي | AM5: =C5-U5 -> 0 | AN5: =D5-V5 -> 0 | AO5: =E5-W5 -> 5 | AP5: =F5-X5 -> 5 | AQ5: =G5-Y5 -> 0 | AR5: =H5-Z5 -> 0 | AS5: =I5-AA5 -> 0 | AT5: =J5-AB5 -> 0 | ... AX5: =N5-AF5 -> 2 | AY5: =SUM(AM5:AX5) -> 14 | AZ5: =AX5*$AX$2+AW5*$AW$2+AV5*$AV$2+AU5*$AU$2+AT5*$AT$2+AS5*$AS$2+AR5*$AR$2+AQ5*$AQ$2+AP5*$AP$2+AO5*$AO$2+AN5*$AN$2+AM5*$AM$2 -> 254 | BB5: 3 | BC5: علي اليحيوي | DL5: =SUM(BD5:DK5) -> 0 | DM5: 15 | DN5: =DM5-DL5 -> 15 | DO5: =SUM(DP5:FW5) -> 0 | DP5: =BD5*11 -> 0 | DQ5: =BE5*21 -> 0 | DR5: =BF5*12 -> 0 | DS5: =BG5*22 -> 0 | DT5: =BH5*13 -> 0 | DU5: =BI5*23 -> 0 | DV5: =BJ5*14 -> 0 | DW5: =BK5*24 -> 0 | DX5: =BL5*15 -> 0 | DY5: =BM5*25 -> 0 | DZ5: =BN5*16 -> 0 | EA5: =BO5*26 -> 0 | EB5: =BP5*11 -> 0 | EC5: =BQ5*21 -> 0 | ED5: =BR5*12 -> 0 | EE5: =BS5*22 -> 0 | EF5: =BT5*13 -> 0 | EG5: =BU5*23 -> 0 | EH5: =BV5*14 -> 0 | EI5: =BW5*24 -> 0 | EJ5: =BX5*15 -> 0 | EK5: =BY5*25 -> 0 | EL5: =BZ5*16 -> 0 | EM5: =CA5*26 -> 0 | EN5: =CB5*11 -> 0 | EO5: =CC5*21 -> 0 | EP5: =CD5*12 -> 0 | EQ5: =CE5*22 -> 0 | ER5: =CF5*13 -> 0 | ES5: =CG5*23 -> 0 | ET5: =CH5*14 -> 0 | EU5: =CI5*24 -> 0 | EV5: =CJ5*15 -> 0 | EW5: =CK5*25 -> 0 | EX5: =CL5*16 -> 0 | EY5: =CM5*26 -> 0 | EZ5: =CN5*11 -> 0 | FA5: =CO5*21 -> 0 | FB5: =CP5*12 -> 0 | FC5: =CQ5*22 -> 0 | FD5: =CR5*13 -> 0 | FE5: =CS5*23 -> 0 | FF5: =CT5*14 -> 0 | FG5: =CU5*24 -> 0 | FH5: =CV5*15 -> 0 | FI5: =CW5*25 -> 0 | FJ5: =CX5*16 -> 0 | FK5: =CY5*26 -> 0 | FL5: =CZ5*11 -> 0 | FM5: =DA5*21 -> 0 | FN5: =DB5*12 -> 0 | FO5: =DC5*22 -> 0 | FP5: =DD5*13 -> 0 | FQ5: =DE5*23 -> 0 | FR5: =DF5*14 -> 0 | FS5: =DG5*24 -> 0 | FT5: =DH5*15 -> 0 | FU5: =DI5*25 -> 0 | FV5: =DJ5*16 -> 0 | FW5: =DK5*26 -> 0 | FX5: =#REF! -> #REF! | FY5: =FX5-DO5 -> #REF!
A6: =A5+1 -> 4 | B6: محمد الحجفي | G6: 2 | H6: 2 | I6: 3 | J6: 3 | O6: =SUM(C6:H6) -> 4 | P6: =SUM(I6:N6) -> 6 | Q6: =SUM(C6:N6) -> 10 | S6: =S5+1 -> 4 | T6: =B6 -> محمد الحجفي | AG6: =SUM(U6:Z6) -> 0 | AH6: =SUM(AA6:AF6) -> 0 | AI6: =AH6+AG6 -> 0 | AJ6: 3 | AK6: =AK5+1 -> 4 | AL6: =B6 -> محمد الحجفي | AM6: =C6-U6 -> 0 | AN6: =D6-V6 -> 0 | AO6: =E6-W6 -> 0 | AP6: =F6-X6 -> 0 | AQ6: =G6-Y6 -> 2 | AR6: =H6-Z6 -> 2 | AS6: =I6-AA6 -> 3 | AT6: =J6-AB6 -> 3 | ... AX6: =N6-AF6 -> 0 | AY6: =SUM(AM6:AX6) -> 10 | AZ6: =AX6*$AX$2+AW6*$AW$2+AV6*$AV$2+AU6*$AU$2+AT6*$AT$2+AS6*$AS$2+AR6*$AR$2+AQ6*$AQ$2+AP6*$AP$2+AO6*$AO$2+AN6*$AN$2+AM6*$AM$2 -> 186 | BB6: 4 | BC6: جبر الغزواني | DL6: =SUM(BD6:DK6) -> 0 | DM6: 15 | DN6: =DM6-DL6 -> 15 | DO6: =SUM(DP6:FW6) -> 0 | DP6: =BD6*11 -> 0 | DQ6: =BE6*21 -> 0 | DR6: =BF6*12 -> 0 | DS6: =BG6*22 -> 0 | DT6: =BH6*13 -> 0 | DU6: =BI6*23 -> 0 | DV6: =BJ6*14 -> 0 | DW6: =BK6*24 -> 0 | DX6: =BL6*15 -> 0 | DY6: =BM6*25 -> 0 | DZ6: =BN6*16 -> 0 | EA6: =BO6*26 -> 0 | EB6: =BP6*11 -> 0 | EC6: =BQ6*21 -> 0 | ED6: =BR6*12 -> 0 | EE6: =BS6*22 -> 0 | EF6: =BT6*13 -> 0 | EG6: =BU6*23 -> 0 | EH6: =BV6*14 -> 0 | EI6: =BW6*24 -> 0 | EJ6: =BX6*15 -> 0 | EK6: =BY6*25 -> 0 | EL6: =BZ6*16 -> 0 | EM6: =CA6*26 -> 0 | EN6: =CB6*11 -> 0 | EO6: =CC6*21 -> 0 | EP6: =CD6*12 -> 0 | EQ6: =CE6*22 -> 0 | ER6: =CF6*13 -> 0 | ES6: =CG6*23 -> 0 | ET6: =CH6*14 -> 0 | EU6: =CI6*24 -> 0 | EV6: =CJ6*15 -> 0 | EW6: =CK6*25 -> 0 | EX6: =CL6*16 -> 0 | EY6: =CM6*26 -> 0 | EZ6: =CN6*11 -> 0 | FA6: =CO6*21 -> 0 | FB6: =CP6*12 -> 0 | FC6: =CQ6*22 -> 0 | FD6: =CR6*13 -> 0 | FE6: =CS6*23 -> 0 | FF6: =CT6*14 -> 0 | FG6: =CU6*24 -> 0 | FH6: =CV6*15 -> 0 | FI6: =CW6*25 -> 0 | FJ6: =CX6*16 -> 0 | FK6: =CY6*26 -> 0 | FL6: =CZ6*11 -> 0 | FM6: =DA6*21 -> 0 | FN6: =DB6*12 -> 0 | FO6: =DC6*22 -> 0 | FP6: =DD6*13 -> 0 | FQ6: =DE6*23 -> 0 | FR6: =DF6*14 -> 0 | FS6: =DG6*24 -> 0 | FT6: =DH6*15 -> 0 | FU6: =DI6*25 -> 0 | FV6: =DJ6*16 -> 0 | FW6: =DK6*26 -> 0 | FX6: =#REF! -> #REF! | FY6: =FX6-DO6 -> #REF!
A7: =A6+1 -> 5 | B7: أبو عاصم | I7: 4 | J7: 4 | O7: =SUM(C7:H7) -> 0 | P7: =SUM(I7:N7) -> 8 | Q7: =SUM(C7:N7) -> 8 | S7: =S6+1 -> 5 | T7: =B7 -> أبو عاصم | AG7: =SUM(U7:Z7) -> 0 | AH7: =SUM(AA7:AF7) -> 0 | AI7: =AH7+AG7 -> 0 | AJ7: 5 | AK7: =AK6+1 -> 5 | AL7: =B7 -> أبو عاصم | AM7: =C7-U7 -> 0 | AN7: =D7-V7 -> 0 | AO7: =E7-W7 -> 0 | AP7: =F7-X7 -> 0 | AQ7: =G7-Y7 -> 0 | AR7: =H7-Z7 -> 0 | AS7: =I7-AA7 -> 4 | AT7: =J7-AB7 -> 4 | ... AX7: =N7-AF7 -> 0 | AY7: =SUM(AM7:AX7) -> 8 | AZ7: =AX7*$AX$2+AW7*$AW$2+AV7*$AV$2+AU7*$AU$2+AT7*$AT$2+AS7*$AS$2+AR7*$AR$2+AQ7*$AQ$2+AP7*$AP$2+AO7*$AO$2+AN7*$AN$2+AM7*$AM$2 -> 152 | BB7: 5 | BC7: حسين العثواني | BD7: 1 | BE7: 1 | BR7: 1 | BS7: 1 | CB7: 1 | CC7: 1 | CE7: 1 | CF7: 1 | CG7: 1 | CN7: 1 | CO7: 1 | CP7: 1 | CR7: 1 | CS7: 1 | DA7: 1 | DB7: 1 | DC7: 1 | DD7: 1 | DE7: 1 | DL7: =SUM(BD7:DK7) -> 19 | DM7: 19 | DN7: =DM7-DL7 -> 0 | DO7: =SUM(DP7:FW7) -> 327 | DP7: =BD7*11 -> 11 | DQ7: =BE7*21 -> 21 | DR7: =BF7*12 -> 0 | DS7: =BG7*22 -> 0 | DT7: =BH7*13 -> 0 | DU7: =BI7*23 -> 0 | DV7: =BJ7*14 -> 0 | DW7: =BK7*24 -> 0 | DX7: =BL7*15 -> 0 | DY7: =BM7*25 -> 0 | DZ7: =BN7*16 -> 0 | EA7: =BO7*26 -> 0 | EB7: =BP7*11 -> 0 | EC7: =BQ7*21 -> 0 | ED7: =BR7*12 -> 12 | EE7: =BS7*22 -> 22 | EF7: =BT7*13 -> 0 | EG7: =BU7*23 -> 0 | EH7: =BV7*14 -> 0 | EI7: =BW7*24 -> 0 | EJ7: =BX7*15 -> 0 | EK7: =BY7*25 -> 0 | EL7: =BZ7*16 -> 0 | EM7: =CA7*26 -> 0 | EN7: =CB7*11 -> 11 | EO7: =CC7*21 -> 21 | EP7: =CD7*12 -> 0 | EQ7: =CE7*22 -> 22 | ER7: =CF7*13 -> 13 | ES7: =CG7*23 -> 23 | ET7: =CH7*14 -> 0 | EU7: =CI7*24 -> 0 | EV7: =CJ7*15 -> 0 | EW7: =CK7*25 -> 0 | EX7: =CL7*16 -> 0 | EY7: =CM7*26 -> 0 | EZ7: =CN7*11 -> 11 | FA7: =CO7*21 -> 21 | FB7: =CP7*12 -> 12 | FC7: =CQ7*22 -> 0 | FD7: =CR7*13 -> 13 | FE7: =CS7*23 -> 23 | FF7: =CT7*14 -> 0 | FG7: =CU7*24 -> 0 | FH7: =CV7*15 -> 0 | FI7: =CW7*25 -> 0 | FJ7: =CX7*16 -> 0 | FK7: =CY7*26 -> 0 | FL7: =CZ7*11 -> 0 | FM7: =DA7*21 -> 21 | FN7: =DB7*12 -> 12 | FO7: =DC7*22 -> 22 | FP7: =DD7*13 -> 13 | FQ7: =DE7*23 -> 23 | FR7: =DF7*14 -> 0 | FS7: =DG7*24 -> 0 | FT7: =DH7*15 -> 0 | FU7: =DI7*25 -> 0 | FV7: =DJ7*16 -> 0 | FW7: =DK7*26 -> 0 | FX7: =#REF! -> #REF! | FY7: =FX7-DO7 -> #REF!
A8: =A7+1 -> 6 | B8: علي اليحيوي | C8: 5 | E8: 5 | F8: 5 | O8: =SUM(C8:H8) -> 15 | P8: =SUM(I8:N8) -> 0 | Q8: =SUM(C8:N8) -> 15 | S8: =S7+1 -> 6 | T8: =B8 -> علي اليحيوي | AG8: =SUM(U8:Z8) -> 0 | AH8: =SUM(AA8:AF8) -> 0 | AI8: =AH8+AG8 -> 0 | AJ8: 3 | AK8: =AK7+1 -> 6 | AL8: =B8 -> علي اليحيوي | AM8: =C8-U8 -> 5 | AN8: =D8-V8 -> 0 | AO8: =E8-W8 -> 5 | AP8: =F8-X8 -> 5 | AQ8: =G8-Y8 -> 0 | AR8: =H8-Z8 -> 0 | AS8: =I8-AA8 -> 0 | AT8: =J8-AB8 -> 0 | ... AX8: =N8-AF8 -> 0 | AY8: =SUM(AM8:AX8) -> 15 | AZ8: =AX8*$AX$2+AW8*$AW$2+AV8*$AV$2+AU8*$AU$2+AT8*$AT$2+AS8*$AS$2+AR8*$AR$2+AQ8*$AQ$2+AP8*$AP$2+AO8*$AO$2+AN8*$AN$2+AM8*$AM$2 -> 225 | BB8: 6 | BC8: علي النشمي | DL8: =SUM(BD8:DK8) -> 0 | DM8: 17 | DN8: =DM8-DL8 -> 17 | DO8: =SUM(DP8:FW8) -> 0 | DP8: =BD8*11 -> 0 | DQ8: =BE8*21 -> 0 | DR8: =BF8*12 -> 0 | DS8: =BG8*22 -> 0 | DT8: =BH8*13 -> 0 | DU8: =BI8*23 -> 0 | DV8: =BJ8*14 -> 0 | DW8: =BK8*24 -> 0 | DX8: =BL8*15 -> 0 | DY8: =BM8*25 -> 0 | DZ8: =BN8*16 -> 0 | EA8: =BO8*26 -> 0 | EB8: =BP8*11 -> 0 | EC8: =BQ8*21 -> 0 | ED8: =BR8*12 -> 0 | EE8: =BS8*22 -> 0 | EF8: =BT8*13 -> 0 | EG8: =BU8*23 -> 0 | EH8: =BV8*14 -> 0 | EI8: =BW8*24 -> 0 | EJ8: =BX8*15 -> 0 | EK8: =BY8*25 -> 0 | EL8: =BZ8*16 -> 0 | EM8: =CA8*26 -> 0 | EN8: =CB8*11 -> 0 | EO8: =CC8*21 -> 0 | EP8: =CD8*12 -> 0 | EQ8: =CE8*22 -> 0 | ER8: =CF8*13 -> 0 | ES8: =CG8*23 -> 0 | ET8: =CH8*14 -> 0 | EU8: =CI8*24 -> 0 | EV8: =CJ8*15 -> 0 | EW8: =CK8*25 -> 0 | EX8: =CL8*16 -> 0 | EY8: =CM8*26 -> 0 | EZ8: =CN8*11 -> 0 | FA8: =CO8*21 -> 0 | FB8: =CP8*12 -> 0 | FC8: =CQ8*22 -> 0 | FD8: =CR8*13 -> 0 | FE8: =CS8*23 -> 0 | FF8: =CT8*14 -> 0 | FG8: =CU8*24 -> 0 | FH8: =CV8*15 -> 0 | FI8: =CW8*25 -> 0 | FJ8: =CX8*16 -> 0 | FK8: =CY8*26 -> 0 | FL8: =CZ8*11 -> 0 | FM8: =DA8*21 -> 0 | FN8: =DB8*12 -> 0 | FO8: =DC8*22 -> 0 | FP8: =DD8*13 -> 0 | FQ8: =DE8*23 -> 0 | FR8: =DF8*14 -> 0 | FS8: =DG8*24 -> 0 | FT8: =DH8*15 -> 0 | FU8: =DI8*25 -> 0 | FV8: =DJ8*16 -> 0 | FW8: =DK8*26 -> 0 | FX8: =#REF! -> #REF! | FY8: =FX8-DO8 -> #REF!
A9: =A8+1 -> 7 | B9: جبر الغزواني | G9: 5 | H9: 5 | O9: =SUM(C9:H9) -> 10 | P9: =SUM(I9:N9) -> 0 | Q9: =SUM(C9:N9) -> 10 | S9: =S8+1 -> 7 | T9: =B9 -> جبر الغزواني | AG9: =SUM(U9:Z9) -> 0 | AH9: =SUM(AA9:AF9) -> 0 | AI9: =AH9+AG9 -> 0 | AJ9: 3 | AK9: =AK8+1 -> 7 | AL9: =B9 -> جبر الغزواني | AM9: =C9-U9 -> 0 | AN9: =D9-V9 -> 0 | AO9: =E9-W9 -> 0 | AP9: =F9-X9 -> 0 | AQ9: =G9-Y9 -> 5 | AR9: =H9-Z9 -> 5 | AS9: =I9-AA9 -> 0 | AT9: =J9-AB9 -> 0 | ... AX9: =N9-AF9 -> 0 | AY9: =SUM(AM9:AX9) -> 10 | AZ9: =AX9*$AX$2+AW9*$AW$2+AV9*$AV$2+AU9*$AU$2+AT9*$AT$2+AS9*$AS$2+AR9*$AR$2+AQ9*$AQ$2+AP9*$AP$2+AO9*$AO$2+AN9*$AN$2+AM9*$AM$2 -> 180 | BB9: 7 | BC9: عبده | DL9: =SUM(BD9:DK9) -> 0 | DM9: 15 | DN9: =DM9-DL9 -> 15 | DO9: =SUM(DP9:FW9) -> 0 | DP9: =BD9*11 -> 0 | DQ9: =BE9*21 -> 0 | DR9: =BF9*12 -> 0 | DS9: =BG9*22 -> 0 | DT9: =BH9*13 -> 0 | DU9: =BI9*23 -> 0 | DV9: =BJ9*14 -> 0 | DW9: =BK9*24 -> 0 | DX9: =BL9*15 -> 0 | DY9: =BM9*25 -> 0 | DZ9: =BN9*16 -> 0 | EA9: =BO9*26 -> 0 | EB9: =BP9*11 -> 0 | EC9: =BQ9*21 -> 0 | ED9: =BR9*12 -> 0 | EE9: =BS9*22 -> 0 | EF9: =BT9*13 -> 0 | EG9: =BU9*23 -> 0 | EH9: =BV9*14 -> 0 | EI9: =BW9*24 -> 0 | EJ9: =BX9*15 -> 0 | EK9: =BY9*25 -> 0 | EL9: =BZ9*16 -> 0 | EM9: =CA9*26 -> 0 | EN9: =CB9*11 -> 0 | EO9: =CC9*21 -> 0 | EP9: =CD9*12 -> 0 | EQ9: =CE9*22 -> 0 | ER9: =CF9*13 -> 0 | ES9: =CG9*23 -> 0 | ET9: =CH9*14 -> 0 | EU9: =CI9*24 -> 0 | EV9: =CJ9*15 -> 0 | EW9: =CK9*25 -> 0 | EX9: =CL9*16 -> 0 | EY9: =CM9*26 -> 0 | EZ9: =CN9*11 -> 0 | FA9: =CO9*21 -> 0 | FB9: =CP9*12 -> 0 | FC9: =CQ9*22 -> 0 | FD9: =CR9*13 -> 0 | FE9: =CS9*23 -> 0 | FF9: =CT9*14 -> 0 | FG9: =CU9*24 -> 0 | FH9: =CV9*15 -> 0 | FI9: =CW9*25 -> 0 | FJ9: =CX9*16 -> 0 | FK9: =CY9*26 -> 0 | FL9: =CZ9*11 -> 0 | FM9: =DA9*21 -> 0 | FN9: =DB9*12 -> 0 | FO9: =DC9*22 -> 0 | FP9: =DD9*13 -> 0 | FQ9: =DE9*23 -> 0 | FR9: =DF9*14 -> 0 | FS9: =DG9*24 -> 0 | FT9: =DH9*15 -> 0 | FU9: =DI9*25 -> 0 | FV9: =DJ9*16 -> 0 | FW9: =DK9*26 -> 0 | FX9: =#REF! -> #REF! | FY9: =FX9-DO9 -> #REF!
A10: =A9+1 -> 8 | B10: حسين العثواني | C10: 4 | K10: 4 | L10: 4 | O10: =SUM(C10:H10) -> 4 | P10: =SUM(I10:N10) -> 8 | Q10: =SUM(C10:N10) -> 12 | S10: =S9+1 -> 8 | T10: =B10 -> حسين العثواني | AG10: =SUM(U10:Z10) -> 0 | AH10: =SUM(AA10:AF10) -> 0 | AI10: =AH10+AG10 -> 0 | AJ10: 0 | AK10: =AK9+1 -> 8 | AL10: =B10 -> حسين العثواني | AM10: =C10-U10 -> 4 | AN10: =D10-V10 -> 0 | AO10: =E10-W10 -> 0 | AP10: =F10-X10 -> 0 | AQ10: =G10-Y10 -> 0 | AR10: =H10-Z10 -> 0 | AS10: =I10-AA10 -> 0 | AT10: =J10-AB10 -> 0 | ... AX10: =N10-AF10 -> 0 | AY10: =SUM(AM10:AX10) -> 12 | AZ10: =AX10*$AX$2+AW10*$AW$2+AV10*$AV$2+AU10*$AU$2+AT10*$AT$2+AS10*$AS$2+AR10*$AR$2+AQ10*$AQ$2+AP10*$AP$2+AO10*$AO$2+AN10*$AN$2+AM10*$AM$2 -> 204 | BB10: 8 | BC10: الفيدلي | DL10: =SUM(BD10:DK10) -> 0 | DM10: 12 | DN10: =DM10-DL10 -> 12 | DO10: =SUM(DP10:FW10) -> 0 | DP10: =BD10*11 -> 0 | DQ10: =BE10*21 -> 0 | DR10: =BF10*12 -> 0 | DS10: =BG10*22 -> 0 | DT10: =BH10*13 -> 0 | DU10: =BI10*23 -> 0 | DV10: =BJ10*14 -> 0 | DW10: =BK10*24 -> 0 | DX10: =BL10*15 -> 0 | DY10: =BM10*25 -> 0 | DZ10: =BN10*16 -> 0 | EA10: =BO10*26 -> 0 | EB10: =BP10*11 -> 0 | EC10: =BQ10*21 -> 0 | ED10: =BR10*12 -> 0 | EE10: =BS10*22 -> 0 | EF10: =BT10*13 -> 0 | EG10: =BU10*23 -> 0 | EH10: =BV10*14 -> 0 | EI10: =BW10*24 -> 0 | EJ10: =BX10*15 -> 0 | EK10: =BY10*25 -> 0 | EL10: =BZ10*16 -> 0 | EM10: =CA10*26 -> 0 | EN10: =CB10*11 -> 0 | EO10: =CC10*21 -> 0 | EP10: =CD10*12 -> 0 | EQ10: =CE10*22 -> 0 | ER10: =CF10*13 -> 0 | ES10: =CG10*23 -> 0 | ET10: =CH10*14 -> 0 | EU10: =CI10*24 -> 0 | EV10: =CJ10*15 -> 0 | EW10: =CK10*25 -> 0 | EX10: =CL10*16 -> 0 | EY10: =CM10*26 -> 0 | EZ10: =CN10*11 -> 0 | FA10: =CO10*21 -> 0 | FB10: =CP10*12 -> 0 | FC10: =CQ10*22 -> 0 | FD10: =CR10*13 -> 0 | FE10: =CS10*23 -> 0 | FF10: =CT10*14 -> 0 | FG10: =CU10*24 -> 0 | FH10: =CV10*15 -> 0 | FI10: =CW10*25 -> 0 | FJ10: =CX10*16 -> 0 | FK10: =CY10*26 -> 0 | FL10: =CZ10*11 -> 0 | FM10: =DA10*21 -> 0 | FN10: =DB10*12 -> 0 | FO10: =DC10*22 -> 0 | FP10: =DD10*13 -> 0 | FQ10: =DE10*23 -> 0 | FR10: =DF10*14 -> 0 | FS10: =DG10*24 -> 0 | FT10: =DH10*15 -> 0 | FU10: =DI10*25 -> 0 | FV10: =DJ10*16 -> 0 | FW10: =DK10*26 -> 0 | FX10: =#REF! -> #REF! | FY10: =FX10-DO10 -> #REF!
A11: =A10+1 -> 9 | B11: احمد يحيى | E11: 6 | F11: 6 | O11: =SUM(C11:H11) -> 12 | P11: =SUM(I11:N11) -> 0 | Q11: =SUM(C11:N11) -> 12 | S11: =S10+1 -> 9 | T11: =B11 -> احمد يحيى | AG11: =SUM(U11:Z11) -> 0 | AH11: =SUM(AA11:AF11) -> 0 | AI11: =AH11+AG11 -> 0 | AJ11: 0 | AK11: =AK10+1 -> 9 | AL11: =B11 -> احمد يحيى | AM11: =C11-U11 -> 0 | AN11: =D11-V11 -> 0 | AO11: =E11-W11 -> 6 | AP11: =F11-X11 -> 6 | AQ11: =G11-Y11 -> 0 | AR11: =H11-Z11 -> 0 | AS11: =I11-AA11 -> 0 | AT11: =J11-AB11 -> 0 | ... AX11: =N11-AF11 -> 0 | AY11: =SUM(AM11:AX11) -> 12 | AZ11: =AX11*$AX$2+AW11*$AW$2+AV11*$AV$2+AU11*$AU$2+AT11*$AT$2+AS11*$AS$2+AR11*$AR$2+AQ11*$AQ$2+AP11*$AP$2+AO11*$AO$2+AN11*$AN$2+AM11*$AM$2 -> 204 | BB11: 9 | BC11: يحيى العزي | DL11: =SUM(BD11:DK11) -> 0 | DM11: 12 | DN11: =DM11-DL11 -> 12 | DO11: =SUM(DP11:FW11) -> 0 | DP11: =BD11*11 -> 0 | DQ11: =BE11*21 -> 0 | DR11: =BF11*12 -> 0 | DS11: =BG11*22 -> 0 | DT11: =BH11*13 -> 0 | DU11: =BI11*23 -> 0 | DV11: =BJ11*14 -> 0 | DW11: =BK11*24 -> 0 | DX11: =BL11*15 -> 0 | DY11: =BM11*25 -> 0 | DZ11: =BN11*16 -> 0 | EA11: =BO11*26 -> 0 | EB11: =BP11*11 -> 0 | EC11: =BQ11*21 -> 0 | ED11: =BR11*12 -> 0 | EE11: =BS11*22 -> 0 | EF11: =BT11*13 -> 0 | EG11: =BU11*23 -> 0 | EH11: =BV11*14 -> 0 | EI11: =BW11*24 -> 0 | EJ11: =BX11*15 -> 0 | EK11: =BY11*25 -> 0 | EL11: =BZ11*16 -> 0 | EM11: =CA11*26 -> 0 | EN11: =CB11*11 -> 0 | EO11: =CC11*21 -> 0 | EP11: =CD11*12 -> 0 | EQ11: =CE11*22 -> 0 | ER11: =CF11*13 -> 0 | ES11: =CG11*23 -> 0 | ET11: =CH11*14 -> 0 | EU11: =CI11*24 -> 0 | EV11: =CJ11*15 -> 0 | EW11: =CK11*25 -> 0 | EX11: =CL11*16 -> 0 | EY11: =CM11*26 -> 0 | EZ11: =CN11*11 -> 0 | FA11: =CO11*21 -> 0 | FB11: =CP11*12 -> 0 | FC11: =CQ11*22 -> 0 | FD11: =CR11*13 -> 0 | FE11: =CS11*23 -> 0 | FF11: =CT11*14 -> 0 | FG11: =CU11*24 -> 0 | FH11: =CV11*15 -> 0 | FI11: =CW11*25 -> 0 | FJ11: =CX11*16 -> 0 | FK11: =CY11*26 -> 0 | FL11: =CZ11*11 -> 0 | FM11: =DA11*21 -> 0 | FN11: =DB11*12 -> 0 | FO11: =DC11*22 -> 0 | FP11: =DD11*13 -> 0 | FQ11: =DE11*23 -> 0 | FR11: =DF11*14 -> 0 | FS11: =DG11*24 -> 0 | FT11: =DH11*15 -> 0 | FU11: =DI11*25 -> 0 | FV11: =DJ11*16 -> 0 | FW11: =DK11*26 -> 0 | FX11: =#REF! -> #REF! | FY11: =FX11-DO11 -> #REF!
A12: =A11+1 -> 10 | B12: سالم حردان | C12: 3 | E12: 3 | F12: 3 | O12: =SUM(C12:H12) -> 9 | P12: =SUM(I12:N12) -> 0 | Q12: =SUM(C12:N12) -> 9 | S12: =S11+1 -> 10 | T12: =B12 -> سالم حردان | AG12: =SUM(U12:Z12) -> 0 | AH12: =SUM(AA12:AF12) -> 0 | AI12: =AH12+AG12 -> 0 | AJ12: 5 | AK12: =AK11+1 -> 10 | AL12: =B12 -> سالم حردان | AM12: =C12-U12 -> 3 | AN12: =D12-V12 -> 0 | AO12: =E12-W12 -> 3 | AP12: =F12-X12 -> 3 | AQ12: =G12-Y12 -> 0 | AR12: =H12-Z12 -> 0 | AS12: =I12-AA12 -> 0 | AT12: =J12-AB12 -> 0 | ... AX12: =N12-AF12 -> 0 | AY12: =SUM(AM12:AX12) -> 9 | AZ12: =AX12*$AX$2+AW12*$AW$2+AV12*$AV$2+AU12*$AU$2+AT12*$AT$2+AS12*$AS$2+AR12*$AR$2+AQ12*$AQ$2+AP12*$AP$2+AO12*$AO$2+AN12*$AN$2+AM12*$AM$2 -> 135 | BB12: 11 | BC12: فرحان علي | DL12: =SUM(BD12:DK12) -> 0 | DM12: 17 | DN12: =DM12-DL12 -> 17 | DO12: =SUM(DP12:FW12) -> 0 | DP12: =BD12*11 -> 0 | DQ12: =BE12*21 -> 0 | DR12: =BF12*12 -> 0 | DS12: =BG12*22 -> 0 | DT12: =BH12*13 -> 0 | DU12: =BI12*23 -> 0 | DV12: =BJ12*14 -> 0 | DW12: =BK12*24 -> 0 | DX12: =BL12*15 -> 0 | DY12: =BM12*25 -> 0 | DZ12: =BN12*16 -> 0 | EA12: =BO12*26 -> 0 | EB12: =BP12*11 -> 0 | EC12: =BQ12*21 -> 0 | ED12: =BR12*12 -> 0 | EE12: =BS12*22 -> 0 | EF12: =BT12*13 -> 0 | EG12: =BU12*23 -> 0 | EH12: =BV12*14 -> 0 | EI12: =BW12*24 -> 0 | EJ12: =BX12*15 -> 0 | EK12: =BY12*25 -> 0 | EL12: =BZ12*16 -> 0 | EM12: =CA12*26 -> 0 | EN12: =CB12*11 -> 0 | EO12: =CC12*21 -> 0 | EP12: =CD12*12 -> 0 | EQ12: =CE12*22 -> 0 | ER12: =CF12*13 -> 0 | ES12: =CG12*23 -> 0 | ET12: =CH12*14 -> 0 | EU12: =CI12*24 -> 0 | EV12: =CJ12*15 -> 0 | EW12: =CK12*25 -> 0 | EX12: =CL12*16 -> 0 | EY12: =CM12*26 -> 0 | EZ12: =CN12*11 -> 0 | FA12: =CO12*21 -> 0 | FB12: =CP12*12 -> 0 | FC12: =CQ12*22 -> 0 | FD12: =CR12*13 -> 0 | FE12: =CS12*23 -> 0 | FF12: =CT12*14 -> 0 | FG12: =CU12*24 -> 0 | FH12: =CV12*15 -> 0 | FI12: =CW12*25 -> 0 | FJ12: =CX12*16 -> 0 | FK12: =CY12*26 -> 0 | FL12: =CZ12*11 -> 0 | FM12: =DA12*21 -> 0 | FN12: =DB12*12 -> 0 | FO12: =DC12*22 -> 0 | FP12: =DD12*13 -> 0 | FQ12: =DE12*23 -> 0 | FR12: =DF12*14 -> 0 | FS12: =DG12*24 -> 0 | FT12: =DH12*15 -> 0 | FU12: =DI12*25 -> 0 | FV12: =DJ12*16 -> 0 | FW12: =DK12*26 -> 0 | FX12: =#REF! -> #REF! | FY12: =FX12-DO12 -> #REF!
A13: =A12+1 -> 11 | B13: الفيدلي | C13: 2 | E13: 2 | F13: 2 | G13: 2 | H13: 2 | O13: =SUM(C13:H13) -> 10 | P13: =SUM(I13:N13) -> 0 | Q13: =SUM(C13:N13) -> 10 | S13: =S12+1 -> 11 | T13: =B13 -> الفيدلي | AG13: =SUM(U13:Z13) -> 0 | AH13: =SUM(AA13:AF13) -> 0 | AI13: =AH13+AG13 -> 0 | AJ13: 3 | AK13: =AK12+1 -> 11 | AL13: =B13 -> الفيدلي | AM13: =C13-U13 -> 2 | AN13: =D13-V13 -> 0 | AO13: =E13-W13 -> 2 | AP13: =F13-X13 -> 2 | AQ13: =G13-Y13 -> 2 | AR13: =H13-Z13 -> 2 | AS13: =I13-AA13 -> 0 | AT13: =J13-AB13 -> 0 | ... AX13: =N13-AF13 -> 0 | AY13: =SUM(AM13:AX13) -> 10 | AZ13: =AX13*$AX$2+AW13*$AW$2+AV13*$AV$2+AU13*$AU$2+AT13*$AT$2+AS13*$AS$2+AR13*$AR$2+AQ13*$AQ$2+AP13*$AP$2+AO13*$AO$2+AN13*$AN$2+AM13*$AM$2 -> 162 | BB13: 12 | BC13: جبران علي | DL13: =SUM(BD13:DK13) -> 0 | DM13: 17 | DN13: =DM13-DL13 -> 17 | DO13: =SUM(DP13:FW13) -> 0 | DP13: =BD13*11 -> 0 | DQ13: =BE13*21 -> 0 | DR13: =BF13*12 -> 0 | DS13: =BG13*22 -> 0 | DT13: =BH13*13 -> 0 | DU13: =BI13*23 -> 0 | DV13: =BJ13*14 -> 0 | DW13: =BK13*24 -> 0 | DX13: =BL13*15 -> 0 | DY13: =BM13*25 -> 0 | DZ13: =BN13*16 -> 0 | EA13: =BO13*26 -> 0 | EB13: =BP13*11 -> 0 | EC13: =BQ13*21 -> 0 | ED13: =BR13*12 -> 0 | EE13: =BS13*22 -> 0 | EF13: =BT13*13 -> 0 | EG13: =BU13*23 -> 0 | EH13: =BV13*14 -> 0 | EI13: =BW13*24 -> 0 | EJ13: =BX13*15 -> 0 | EK13: =BY13*25 -> 0 | EL13: =BZ13*16 -> 0 | EM13: =CA13*26 -> 0 | EN13: =CB13*11 -> 0 | EO13: =CC13*21 -> 0 | EP13: =CD13*12 -> 0 | EQ13: =CE13*22 -> 0 | ER13: =CF13*13 -> 0 | ES13: =CG13*23 -> 0 | ET13: =CH13*14 -> 0 | EU13: =CI13*24 -> 0 | EV13: =CJ13*15 -> 0 | EW13: =CK13*25 -> 0 | EX13: =CL13*16 -> 0 | EY13: =CM13*26 -> 0 | EZ13: =CN13*11 -> 0 | FA13: =CO13*21 -> 0 | FB13: =CP13*12 -> 0 | FC13: =CQ13*22 -> 0 | FD13: =CR13*13 -> 0 | FE13: =CS13*23 -> 0 | FF13: =CT13*14 -> 0 | FG13: =CU13*24 -> 0 | FH13: =CV13*15 -> 0 | FI13: =CW13*25 -> 0 | FJ13: =CX13*16 -> 0 | FK13: =CY13*26 -> 0 | FL13: =CZ13*11 -> 0 | FM13: =DA13*21 -> 0 | FN13: =DB13*12 -> 0 | FO13: =DC13*22 -> 0 | FP13: =DD13*13 -> 0 | FQ13: =DE13*23 -> 0 | FR13: =DF13*14 -> 0 | FS13: =DG13*24 -> 0 | FT13: =DH13*15 -> 0 | FU13: =DI13*25 -> 0 | FV13: =DJ13*16 -> 0 | FW13: =DK13*26 -> 0 | FX13: =#REF! -> #REF! | FY13: =FX13-DO13 -> #REF!
A14: =A13+1 -> 12 | B14: يحيى العزي | G14: 4 | H14: 4 | I14: 5 | J14: 5 | O14: =SUM(C14:H14) -> 8 | P14: =SUM(I14:N14) -> 10 | Q14: =SUM(C14:N14) -> 18 | S14: =S13+1 -> 12 | T14: =B14 -> يحيى العزي | AG14: =SUM(U14:Z14) -> 0 | AH14: =SUM(AA14:AF14) -> 0 | AI14: =AH14+AG14 -> 0 | AJ14: 1 | AK14: =AK13+1 -> 12 | AL14: =B14 -> يحيى العزي | AM14: =C14-U14 -> 0 | AN14: =D14-V14 -> 0 | AO14: =E14-W14 -> 0 | AP14: =F14-X14 -> 0 | AQ14: =G14-Y14 -> 4 | AR14: =H14-Z14 -> 4 | AS14: =I14-AA14 -> 5 | AT14: =J14-AB14 -> 5 | ... AX14: =N14-AF14 -> 0 | AY14: =SUM(AM14:AX14) -> 18 | AZ14: =AX14*$AX$2+AW14*$AW$2+AV14*$AV$2+AU14*$AU$2+AT14*$AT$2+AS14*$AS$2+AR14*$AR$2+AQ14*$AQ$2+AP14*$AP$2+AO14*$AO$2+AN14*$AN$2+AM14*$AM$2 -> 334 | BB14: 13 | BC14: يحيى احمد | DL14: =SUM(BD14:DK14) -> 0 | DM14: 12 | DN14: =DM14-DL14 -> 12 | DO14: =SUM(DP14:FW14) -> 0 | DP14: =BD14*11 -> 0 | DQ14: =BE14*21 -> 0 | DR14: =BF14*12 -> 0 | DS14: =BG14*22 -> 0 | DT14: =BH14*13 -> 0 | DU14: =BI14*23 -> 0 | DV14: =BJ14*14 -> 0 | DW14: =BK14*24 -> 0 | DX14: =BL14*15 -> 0 | DY14: =BM14*25 -> 0 | DZ14: =BN14*16 -> 0 | EA14: =BO14*26 -> 0 | EB14: =BP14*11 -> 0 | EC14: =BQ14*21 -> 0 | ED14: =BR14*12 -> 0 | EE14: =BS14*22 -> 0 | EF14: =BT14*13 -> 0 | EG14: =BU14*23 -> 0 | EH14: =BV14*14 -> 0 | EI14: =BW14*24 -> 0 | EJ14: =BX14*15 -> 0 | EK14: =BY14*25 -> 0 | EL14: =BZ14*16 -> 0 | EM14: =CA14*26 -> 0 | EN14: =CB14*11 -> 0 | EO14: =CC14*21 -> 0 | EP14: =CD14*12 -> 0 | EQ14: =CE14*22 -> 0 | ER14: =CF14*13 -> 0 | ES14: =CG14*23 -> 0 | ET14: =CH14*14 -> 0 | EU14: =CI14*24 -> 0 | EV14: =CJ14*15 -> 0 | EW14: =CK14*25 -> 0 | EX14: =CL14*16 -> 0 | EY14: =CM14*26 -> 0 | EZ14: =CN14*11 -> 0 | FA14: =CO14*21 -> 0 | FB14: =CP14*12 -> 0 | FC14: =CQ14*22 -> 0 | FD14: =CR14*13 -> 0 | FE14: =CS14*23 -> 0 | FF14: =CT14*14 -> 0 | FG14: =CU14*24 -> 0 | FH14: =CV14*15 -> 0 | FI14: =CW14*25 -> 0 | FJ14: =CX14*16 -> 0 | FK14: =CY14*26 -> 0 | FL14: =CZ14*11 -> 0 | FM14: =DA14*21 -> 0 | FN14: =DB14*12 -> 0 | FO14: =DC14*22 -> 0 | FP14: =DD14*13 -> 0 | FQ14: =DE14*23 -> 0 | FR14: =DF14*14 -> 0 | FS14: =DG14*24 -> 0 | FT14: =DH14*15 -> 0 | FU14: =DI14*25 -> 0 | FV14: =DJ14*16 -> 0 | FW14: =DK14*26 -> 0 | FX14: =#REF! -> #REF! | FY14: =FX14-DO14 -> #REF!
A15: =A14+1 -> 13 | B15: جبران علي | G15: 6 | I15: 5 | J15: 5 | O15: =SUM(C15:H15) -> 6 | P15: =SUM(I15:N15) -> 10 | Q15: =SUM(C15:N15) -> 16 | S15: =S14+1 -> 13 | T15: =B15 -> جبران علي | AG15: =SUM(U15:AB15) -> 0 | AH15: =SUM(AA15:AF15) -> 0 | AI15: =AH15+AG15 -> 0 | AJ15: 3 | AK15: =AK14+1 -> 13 | AL15: =B15 -> جبران علي | AM15: =C15-U15 -> 0 | AN15: =D15-V15 -> 0 | AO15: =E15-W15 -> 0 | AP15: =F15-X15 -> 0 | AQ15: =G15-Y15 -> 6 | AR15: =H15-Z15 -> 0 | AS15: =I15-AA15 -> 5 | AT15: =J15-AB15 -> 5 | ... AX15: =N15-AF15 -> 0 | AY15: =SUM(AM15:AX15) -> 16 | AZ15: =AX15*$AX$2+AW15*$AW$2+AV15*$AV$2+AU15*$AU$2+AT15*$AT$2+AS15*$AS$2+AR15*$AR$2+AQ15*$AQ$2+AP15*$AP$2+AO15*$AO$2+AN15*$AN$2+AM15*$AM$2 -> 268 | BB15: 14 | BC15: ماهر | DL15: =SUM(BD15:DK15) -> 0 | DM15: 17 | DN15: =DM15-DL15 -> 17 | DO15: =SUM(DP15:FW15) -> 0 | DP15: =BD15*11 -> 0 | DQ15: =BE15*21 -> 0 | DR15: =BF15*12 -> 0 | DS15: =BG15*22 -> 0 | DT15: =BH15*13 -> 0 | DU15: =BI15*23 -> 0 | DV15: =BJ15*14 -> 0 | DW15: =BK15*24 -> 0 | DX15: =BL15*15 -> 0 | DY15: =BM15*25 -> 0 | DZ15: =BN15*16 -> 0 | EA15: =BO15*26 -> 0 | EB15: =BP15*11 -> 0 | EC15: =BQ15*21 -> 0 | ED15: =BR15*12 -> 0 | EE15: =BS15*22 -> 0 | EF15: =BT15*13 -> 0 | EG15: =BU15*23 -> 0 | EH15: =BV15*14 -> 0 | EI15: =BW15*24 -> 0 | EJ15: =BX15*15 -> 0 | EK15: =BY15*25 -> 0 | EL15: =BZ15*16 -> 0 | EM15: =CA15*26 -> 0 | EN15: =CB15*11 -> 0 | EO15: =CC15*21 -> 0 | EP15: =CD15*12 -> 0 | EQ15: =CE15*22 -> 0 | ER15: =CF15*13 -> 0 | ES15: =CG15*23 -> 0 | ET15: =CH15*14 -> 0 | EU15: =CI15*24 -> 0 | EV15: =CJ15*15 -> 0 | EW15: =CK15*25 -> 0 | EX15: =CL15*16 -> 0 | EY15: =CM15*26 -> 0 | EZ15: =CN15*11 -> 0 | FA15: =CO15*21 -> 0 | FB15: =CP15*12 -> 0 | FC15: =CQ15*22 -> 0 | FD15: =CR15*13 -> 0 | FE15: =CS15*23 -> 0 | FF15: =CT15*14 -> 0 | FG15: =CU15*24 -> 0 | FH15: =CV15*15 -> 0 | FI15: =CW15*25 -> 0 | FJ15: =CX15*16 -> 0 | FK15: =CY15*26 -> 0 | FL15: =CZ15*11 -> 0 | FM15: =DA15*21 -> 0 | FN15: =DB15*12 -> 0 | FO15: =DC15*22 -> 0 | FP15: =DD15*13 -> 0 | FQ15: =DE15*23 -> 0 | FR15: =DF15*14 -> 0 | FS15: =DG15*24 -> 0 | FT15: =DH15*15 -> 0 | FU15: =DI15*25 -> 0 | FV15: =DJ15*16 -> 0 | FW15: =DK15*26 -> 0 | FX15: =#REF! -> #REF! | FY15: =FX15-DO15 -> #REF!
A16: =A15+1 -> 14 | B16: يحيى احمد | C16: 2 | E16: 2 | G16: 2 | I16: 2 | M16: 3 | O16: =SUM(C16:H16) -> 6 | P16: =SUM(I16:N16) -> 5 | Q16: =SUM(C16:N16) -> 11 | S16: =S15+1 -> 14 | T16: =B16 -> يحيى احمد | AG16: =SUM(U16:AB16) -> 0 | AH16: =SUM(AA16:AF16) -> 0 | AI16: =AH16+AG16 -> 0 | AJ16: 4 | AK16: =AK15+1 -> 14 | AL16: =B16 -> يحيى احمد | AM16: =C16-U16 -> 2 | AN16: =D16-V16 -> 0 | AO16: =E16-W16 -> 2 | AP16: =F16-X16 -> 0 | AQ16: =G16-Y16 -> 2 | AR16: =H16-Z16 -> 0 | AS16: =I16-AA16 -> 2 | AT16: =J16-AB16 -> 0 | ... AX16: =N16-AF16 -> 0 | AY16: =SUM(AM16:AX16) -> 11 | AZ16: =AX16*$AX$2+AW16*$AW$2+AV16*$AV$2+AU16*$AU$2+AT16*$AT$2+AS16*$AS$2+AR16*$AR$2+AQ16*$AQ$2+AP16*$AP$2+AO16*$AO$2+AN16*$AN$2+AM16*$AM$2 -> 148 | BB16: 15 | BC16: ابوعاصم | DL16: =SUM(BD16:DK16) -> 0 | DM16: 14 | DN16: =DM16-DL16 -> 14 | DO16: =SUM(DP16:FW16) -> 0 | DP16: =BD16*11 -> 0 | DQ16: =BE16*21 -> 0 | DR16: =BF16*12 -> 0 | DS16: =BG16*22 -> 0 | DT16: =BH16*13 -> 0 | DU16: =BI16*23 -> 0 | DV16: =BJ16*14 -> 0 | DW16: =BK16*24 -> 0 | DX16: =BL16*15 -> 0 | DY16: =BM16*25 -> 0 | DZ16: =BN16*16 -> 0 | EA16: =BO16*26 -> 0 | EB16: =BP16*11 -> 0 | EC16: =BQ16*21 -> 0 | ED16: =BR16*12 -> 0 | EE16: =BS16*22 -> 0 | EF16: =BT16*13 -> 0 | EG16: =BU16*23 -> 0 | EH16: =BV16*14 -> 0 | EI16: =BW16*24 -> 0 | EJ16: =BX16*15 -> 0 | EK16: =BY16*25 -> 0 | EL16: =BZ16*16 -> 0 | EM16: =CA16*26 -> 0 | EN16: =CB16*11 -> 0 | EO16: =CC16*21 -> 0 | EP16: =CD16*12 -> 0 | EQ16: =CE16*22 -> 0 | ER16: =CF16*13 -> 0 | ES16: =CG16*23 -> 0 | ET16: =CH16*14 -> 0 | EU16: =CI16*24 -> 0 | EV16: =CJ16*15 -> 0 | EW16: =CK16*25 -> 0 | EX16: =CL16*16 -> 0 | EY16: =CM16*26 -> 0 | EZ16: =CN16*11 -> 0 | FA16: =CO16*21 -> 0 | FB16: =CP16*12 -> 0 | FC16: =CQ16*22 -> 0 | FD16: =CR16*13 -> 0 | FE16: =CS16*23 -> 0 | FF16: =CT16*14 -> 0 | FG16: =CU16*24 -> 0 | FH16: =CV16*15 -> 0 | FI16: =CW16*25 -> 0 | FJ16: =CX16*16 -> 0 | FK16: =CY16*26 -> 0 | FL16: =CZ16*11 -> 0 | FM16: =DA16*21 -> 0 | FN16: =DB16*12 -> 0 | FO16: =DC16*22 -> 0 | FP16: =DD16*13 -> 0 | FQ16: =DE16*23 -> 0 | FR16: =DF16*14 -> 0 | FS16: =DG16*24 -> 0 | FT16: =DH16*15 -> 0 | FU16: =DI16*25 -> 0 | FV16: =DJ16*16 -> 0 | FW16: =DK16*26 -> 0 | FX16: =#REF! -> #REF! | FY16: =FX16-DO16 -> #REF!
A17: =A16+1 -> 15 | B17: أبو محمد | F17: 2 | H17: 2 | J17: 2 | N17: 3 | O17: =SUM(C17:H17) -> 4 | P17: =SUM(I17:N17) -> 5 | Q17: =SUM(C17:N17) -> 9 | S17: =S16+1 -> 15 | T17: =B17 -> أبو محمد | AG17: =SUM(U17:AB17) -> 0 | AH17: =SUM(AA17:AF17) -> 0 | AI17: =AH17+AG17 -> 0 | AJ17: 5 | AK17: =AK16+1 -> 15 | AL17: =B17 -> أبو محمد | AM17: =C17-U17 -> 0 | AN17: =D17-V17 -> 0 | AO17: =E17-W17 -> 0 | AP17: =F17-X17 -> 2 | AQ17: =G17-Y17 -> 0 | AR17: =H17-Z17 -> 2 | AS17: =I17-AA17 -> 0 | AT17: =J17-AB17 -> 2 | ... AX17: =N17-AF17 -> 3 | AY17: =SUM(AM17:AX17) -> 9 | AZ17: =AX17*$AX$2+AW17*$AW$2+AV17*$AV$2+AU17*$AU$2+AT17*$AT$2+AS17*$AS$2+AR17*$AR$2+AQ17*$AQ$2+AP17*$AP$2+AO17*$AO$2+AN17*$AN$2+AM17*$AM$2 -> 216
A18: =A17+1 -> 16 | B18: ماهر | C18: 2 | E18: 2 | F18: 2 | G18: 2 | H18: 2 | I18: 3 | J18: 3 | M18: 2 | N18: 2 | O18: =SUM(C18:H18) -> 10 | P18: =SUM(I18:N18) -> 10 | Q18: =SUM(C18:N18) -> 20 | S18: =S17+1 -> 16 | T18: =B18 -> ماهر | AG18: =SUM(U18:AB18) -> 0 | AH18: =SUM(AA18:AF18) -> 0 | AI18: =AH18+AG18 -> 0 | AJ18: 6 | AK18: =AK17+1 -> 16 | AL18: =B18 -> ماهر | AM18: =C18-U18 -> 2 | AN18: =D18-V18 -> 0 | AO18: =E18-W18 -> 2 | AP18: =F18-X18 -> 2 | AQ18: =G18-Y18 -> 2 | AR18: =H18-Z18 -> 2 | AS18: =I18-AA18 -> 3 | AT18: =J18-AB18 -> 3 | ... AX18: =N18-AF18 -> 2 | AY18: =SUM(AM18:AX18) -> 20 | AZ18: =AX18*$AX$2+AW18*$AW$2+AV18*$AV$2+AU18*$AU$2+AT18*$AT$2+AS18*$AS$2+AR18*$AR$2+AQ18*$AQ$2+AP18*$AP$2+AO18*$AO$2+AN18*$AN$2+AM18*$AM$2 -> 360 | BB18: 16 | BC18: محمد الحجفي | DL18: =SUM(BD18:DK18) -> 0 | DM18: 17 | DN18: =DM18-DL18 -> 17 | DO18: =SUM(DP18:FW18) -> 0 | DP18: =BD18*11 -> 0 | DQ18: =BE18*21 -> 0 | DR18: =BF18*12 -> 0 | DS18: =BG18*22 -> 0 | DT18: =BH18*13 -> 0 | DU18: =BI18*23 -> 0 | DV18: =BJ18*14 -> 0 | DW18: =BK18*24 -> 0 | DX18: =BL18*15 -> 0 | DY18: =BM18*25 -> 0 | DZ18: =BN18*16 -> 0 | EA18: =BO18*26 -> 0 | EB18: =BP18*11 -> 0 | EC18: =BQ18*21 -> 0 | ED18: =BR18*12 -> 0 | EE18: =BS18*22 -> 0 | EF18: =BT18*13 -> 0 | EG18: =BU18*23 -> 0 | EH18: =BV18*14 -> 0 | EI18: =BW18*24 -> 0 | EJ18: =BX18*15 -> 0 | EK18: =BY18*25 -> 0 | EL18: =BZ18*16 -> 0 | EM18: =CA18*26 -> 0 | EN18: =CB18*11 -> 0 | EO18: =CC18*21 -> 0 | EP18: =CD18*12 -> 0 | EQ18: =CE18*22 -> 0 | ER18: =CF18*13 -> 0 | ES18: =CG18*23 -> 0 | ET18: =CH18*14 -> 0 | EU18: =CI18*24 -> 0 | EV18: =CJ18*15 -> 0 | EW18: =CK18*25 -> 0 | EX18: =CL18*16 -> 0 | EY18: =CM18*26 -> 0 | EZ18: =CN18*11 -> 0 | FA18: =CO18*21 -> 0 | FB18: =CP18*12 -> 0 | FC18: =CQ18*22 -> 0 | FD18: =CR18*13 -> 0 | FE18: =CS18*23 -> 0 | FF18: =CT18*14 -> 0 | FG18: =CU18*24 -> 0 | FH18: =CV18*15 -> 0 | FI18: =CW18*25 -> 0 | FJ18: =CX18*16 -> 0 | FK18: =CY18*26 -> 0 | FL18: =CZ18*11 -> 0 | FM18: =DA18*21 -> 0 | FN18: =DB18*12 -> 0 | FO18: =DC18*22 -> 0 | FP18: =DD18*13 -> 0 | FQ18: =DE18*23 -> 0 | FR18: =DF18*14 -> 0 | FS18: =DG18*24 -> 0 | FT18: =DH18*15 -> 0 | FU18: =DI18*25 -> 0 | FV18: =DJ18*16 -> 0 | FW18: =DK18*26 -> 0 | FX18: =#REF! -> #REF! | FY18: =FX18-DO18 -> #REF!
A19: =A18+1 -> 17 | B19: محمد علي | O19: =SUM(C19:H19) -> 0 | P19: =SUM(I19:N19) -> 0 | Q19: =SUM(C19:N19) -> 0 | S19: =S18+1 -> 17 | T19: =B19 -> محمد علي | AG19: =SUM(U19:AB19) -> 0 | AH19: =SUM(AA19:AF19) -> 0 | AI19: =AH19+AG19 -> 0 | AJ19: 7 | AK19: =AK18+1 -> 17 | AL19: =B19 -> محمد علي | AM19: =C19-U19 -> 0 | AN19: =D19-V19 -> 0 | AO19: =E19-W19 -> 0 | AP19: =F19-X19 -> 0 | AQ19: =G19-Y19 -> 0 | AR19: =H19-Z19 -> 0 | AS19: =I19-AA19 -> 0 | AT19: =J19-AB19 -> 0 | ... AX19: =N19-AF19 -> 0 | AY19: =SUM(AM19:AX19) -> 0 | AZ19: =AX19*$AX$2+AW19*$AW$2+AV19*$AV$2+AU19*$AU$2+AT19*$AT$2+AS19*$AS$2+AR19*$AR$2+AQ19*$AQ$2+AP19*$AP$2+AO19*$AO$2+AN19*$AN$2+AM19*$AM$2 -> 0 | BB19: 17 | BC19: عادل الفيفي | DL19: =SUM(BD19:DK19) -> 0 | DM19: 13 | DN19: =DM19-DL19 -> 13 | DO19: =SUM(DP19:FW19) -> 0 | DP19: =BD19*11 -> 0 | DQ19: =BE19*21 -> 0 | DR19: =BF19*12 -> 0 | DS19: =BG19*22 -> 0 | DT19: =BH19*13 -> 0 | DU19: =BI19*23 -> 0 | DV19: =BJ19*14 -> 0 | DW19: =BK19*24 -> 0 | DX19: =BL19*15 -> 0 | DY19: =BM19*25 -> 0 | DZ19: =BN19*16 -> 0 | EA19: =BO19*26 -> 0 | EB19: =BP19*11 -> 0 | EC19: =BQ19*21 -> 0 | ED19: =BR19*12 -> 0 | EE19: =BS19*22 -> 0 | EF19: =BT19*13 -> 0 | EG19: =BU19*23 -> 0 | EH19: =BV19*14 -> 0 | EI19: =BW19*24 -> 0 | EJ19: =BX19*15 -> 0 | EK19: =BY19*25 -> 0 | EL19: =BZ19*16 -> 0 | EM19: =CA19*26 -> 0 | EN19: =CB19*11 -> 0 | EO19: =CC19*21 -> 0 | EP19: =CD19*12 -> 0 | EQ19: =CE19*22 -> 0 | ER19: =CF19*13 -> 0 | ES19: =CG19*23 -> 0 | ET19: =CH19*14 -> 0 | EU19: =CI19*24 -> 0 | EV19: =CJ19*15 -> 0 | EW19: =CK19*25 -> 0 | EX19: =CL19*16 -> 0 | EY19: =CM19*26 -> 0 | EZ19: =CN19*11 -> 0 | FA19: =CO19*21 -> 0 | FB19: =CP19*12 -> 0 | FC19: =CQ19*22 -> 0 | FD19: =CR19*13 -> 0 | FE19: =CS19*23 -> 0 | FF19: =CT19*14 -> 0 | FG19: =CU19*24 -> 0 | FH19: =CV19*15 -> 0 | FI19: =CW19*25 -> 0 | FJ19: =CX19*16 -> 0 | FK19: =CY19*26 -> 0 | FL19: =CZ19*11 -> 0 | FM19: =DA19*21 -> 0 | FN19: =DB19*12 -> 0 | FO19: =DC19*22 -> 0 | FP19: =DD19*13 -> 0 | FQ19: =DE19*23 -> 0 | FR19: =DF19*14 -> 0 | FS19: =DG19*24 -> 0 | FT19: =DH19*15 -> 0 | FU19: =DI19*25 -> 0 | FV19: =DJ19*16 -> 0 | FW19: =DK19*26 -> 0 | FX19: =#REF! -> #REF! | FY19: =FX19-DO19 -> #REF!
A20: =A19+1 -> 18 | B20: سالم يحيى | I20: 4 | J20: 4 | K20: 4 | L20: 4 | O20: =SUM(C20:H20) -> 0 | P20: =SUM(I20:N20) -> 16 | Q20: =SUM(C20:N20) -> 16 | S20: =S19+1 -> 18 | T20: =B20 -> سالم يحيى | AG20: =SUM(U20:AB20) -> 0 | AH20: =SUM(AA20:AF20) -> 0 | AI20: =AH20+AG20 -> 0 | AJ20: 8 | AK20: =AK19+1 -> 18 | AL20: =B20 -> سالم يحيى | AM20: =C20-U20 -> 0 | AN20: =D20-V20 -> 0 | AO20: =E20-W20 -> 0 | AP20: =F20-X20 -> 0 | AQ20: =G20-Y20 -> 0 | AR20: =H20-Z20 -> 0 | AS20: =I20-AA20 -> 4 | AT20: =J20-AB20 -> 4 | ... AX20: =N20-AF20 -> 0 | AY20: =SUM(AM20:AX20) -> 16 | AZ20: =AX20*$AX$2+AW20*$AW$2+AV20*$AV$2+AU20*$AU$2+AT20*$AT$2+AS20*$AS$2+AR20*$AR$2+AQ20*$AQ$2+AP20*$AP$2+AO20*$AO$2+AN20*$AN$2+AM20*$AM$2 -> 312 | BB20: 18 | BC20: سالم يحيى | DL20: =SUM(BD20:DK20) -> 0 | DM20: 13 | DN20: =DM20-DL20 -> 13 | DO20: =SUM(DP20:FW20) -> 0 | DP20: =BD20*11 -> 0 | DQ20: =BE20*21 -> 0 | DR20: =BF20*12 -> 0 | DS20: =BG20*22 -> 0 | DT20: =BH20*13 -> 0 | DU20: =BI20*23 -> 0 | DV20: =BJ20*14 -> 0 | DW20: =BK20*24 -> 0 | DX20: =BL20*15 -> 0 | DY20: =BM20*25 -> 0 | DZ20: =BN20*16 -> 0 | EA20: =BO20*26 -> 0 | EB20: =BP20*11 -> 0 | EC20: =BQ20*21 -> 0 | ED20: =BR20*12 -> 0 | EE20: =BS20*22 -> 0 | EF20: =BT20*13 -> 0 | EG20: =BU20*23 -> 0 | EH20: =BV20*14 -> 0 | EI20: =BW20*24 -> 0 | EJ20: =BX20*15 -> 0 | EK20: =BY20*25 -> 0 | EL20: =BZ20*16 -> 0 | EM20: =CA20*26 -> 0 | EN20: =CB20*11 -> 0 | EO20: =CC20*21 -> 0 | EP20: =CD20*12 -> 0 | EQ20: =CE20*22 -> 0 | ER20: =CF20*13 -> 0 | ES20: =CG20*23 -> 0 | ET20: =CH20*14 -> 0 | EU20: =CI20*24 -> 0 | EV20: =CJ20*15 -> 0 | EW20: =CK20*25 -> 0 | EX20: =CL20*16 -> 0 | EY20: =CM20*26 -> 0 | EZ20: =CN20*11 -> 0 | FA20: =CO20*21 -> 0 | FB20: =CP20*12 -> 0 | FC20: =CQ20*22 -> 0 | FD20: =CR20*13 -> 0 | FE20: =CS20*23 -> 0 | FF20: =CT20*14 -> 0 | FG20: =CU20*24 -> 0 | FH20: =CV20*15 -> 0 | FI20: =CW20*25 -> 0 | FJ20: =CX20*16 -> 0 | FK20: =CY20*26 -> 0 | FL20: =CZ20*11 -> 0 | FM20: =DA20*21 -> 0 | FN20: =DB20*12 -> 0 | FO20: =DC20*22 -> 0 | FP20: =DD20*13 -> 0 | FQ20: =DE20*23 -> 0 | FR20: =DF20*14 -> 0 | FS20: =DG20*24 -> 0 | FT20: =DH20*15 -> 0 | FU20: =DI20*25 -> 0 | FV20: =DJ20*16 -> 0 | FW20: =DK20*26 -> 0 | FX20: =#REF! -> #REF! | FY20: =FX20-DO20 -> #REF!
A21: =A20+1 -> 19 | B21: محمود | M21: 5 | N21: 5 | O21: =SUM(C21:H21) -> 0 | P21: =SUM(I21:N21) -> 10 | Q21: =SUM(C21:N21) -> 10 | S21: =S20+1 -> 19 | T21: =B21 -> محمود | AG21: =SUM(U21:AB21) -> 0 | AH21: =SUM(AA21:AF21) -> 0 | AI21: =AH21+AG21 -> 0 | AJ21: 9 | AK21: =AK20+1 -> 19 | AL21: =B21 -> محمود | AM21: =C21-U21 -> 0 | AN21: =D21-V21 -> 0 | AO21: =E21-W21 -> 0 | AP21: =F21-X21 -> 0 | AQ21: =G21-Y21 -> 0 | AR21: =H21-Z21 -> 0 | AS21: =I21-AA21 -> 0 | AT21: =J21-AB21 -> 0 | ... AX21: =N21-AF21 -> 5 | AY21: =SUM(AM21:AX21) -> 10 | AZ21: =AX21*$AX$2+AW21*$AW$2+AV21*$AV$2+AU21*$AU$2+AT21*$AT$2+AS21*$AS$2+AR21*$AR$2+AQ21*$AQ$2+AP21*$AP$2+AO21*$AO$2+AN21*$AN$2+AM21*$AM$2 -> 210 | BB21: 19 | BC21: محمود | DL21: =SUM(BD21:DK21) -> 0 | DM21: 15 | DN21: =DM21-DL21 -> 15 | DO21: =SUM(DP21:FW21) -> 0 | DP21: =BD21*11 -> 0 | DQ21: =BE21*21 -> 0 | DR21: =BF21*12 -> 0 | DS21: =BG21*22 -> 0 | DT21: =BH21*13 -> 0 | DU21: =BI21*23 -> 0 | DV21: =BJ21*14 -> 0 | DW21: =BK21*24 -> 0 | DX21: =BL21*15 -> 0 | DY21: =BM21*25 -> 0 | DZ21: =BN21*16 -> 0 | EA21: =BO21*26 -> 0 | EB21: =BP21*11 -> 0 | EC21: =BQ21*21 -> 0 | ED21: =BR21*12 -> 0 | EE21: =BS21*22 -> 0 | EF21: =BT21*13 -> 0 | EG21: =BU21*23 -> 0 | EH21: =BV21*14 -> 0 | EI21: =BW21*24 -> 0 | EJ21: =BX21*15 -> 0 | EK21: =BY21*25 -> 0 | EL21: =BZ21*16 -> 0 | EM21: =CA21*26 -> 0 | EN21: =CB21*11 -> 0 | EO21: =CC21*21 -> 0 | EP21: =CD21*12 -> 0 | EQ21: =CE21*22 -> 0 | ER21: =CF21*13 -> 0 | ES21: =CG21*23 -> 0 | ET21: =CH21*14 -> 0 | EU21: =CI21*24 -> 0 | EV21: =CJ21*15 -> 0 | EW21: =CK21*25 -> 0 | EX21: =CL21*16 -> 0 | EY21: =CM21*26 -> 0 | EZ21: =CN21*11 -> 0 | FA21: =CO21*21 -> 0 | FB21: =CP21*12 -> 0 | FC21: =CQ21*22 -> 0 | FD21: =CR21*13 -> 0 | FE21: =CS21*23 -> 0 | FF21: =CT21*14 -> 0 | FG21: =CU21*24 -> 0 | FH21: =CV21*15 -> 0 | FI21: =CW21*25 -> 0 | FJ21: =CX21*16 -> 0 | FK21: =CY21*26 -> 0 | FL21: =CZ21*11 -> 0 | FM21: =DA21*21 -> 0 | FN21: =DB21*12 -> 0 | FO21: =DC21*22 -> 0 | FP21: =DD21*13 -> 0 | FQ21: =DE21*23 -> 0 | FR21: =DF21*14 -> 0 | FS21: =DG21*24 -> 0 | FT21: =DH21*15 -> 0 | FU21: =DI21*25 -> 0 | FV21: =DJ21*16 -> 0 | FW21: =DK21*26 -> 0 | FX21: =#REF! -> #REF! | FY21: =FX21-DO21 -> #REF!
A22: =A21+1 -> 20 | B22: حسين سالم | I22: 3 | J22: 3 | K22: 5 | L22: 5 | O22: =SUM(C22:H22) -> 0 | P22: =SUM(I22:N22) -> 16 | Q22: =SUM(C22:N22) -> 16 | S22: =S21+1 -> 20 | T22: =B22 -> حسين سالم | AG22: =SUM(U22:AB22) -> 0 | AH22: =SUM(AA22:AF22) -> 0 | AI22: =AH22+AG22 -> 0 | AJ22: 10 | AK22: =AK21+1 -> 20 | AL22: =B22 -> حسين سالم | AM22: =C22-U22 -> 0 | AN22: =D22-V22 -> 0 | AO22: =E22-W22 -> 0 | AP22: =F22-X22 -> 0 | AQ22: =G22-Y22 -> 0 | AR22: =H22-Z22 -> 0 | AS22: =I22-AA22 -> 3 | AT22: =J22-AB22 -> 3 | ... AX22: =N22-AF22 -> 0 | AY22: =SUM(AM22:AX22) -> 16 | AZ22: =AX22*$AX$2+AW22*$AW$2+AV22*$AV$2+AU22*$AU$2+AT22*$AT$2+AS22*$AS$2+AR22*$AR$2+AQ22*$AQ$2+AP22*$AP$2+AO22*$AO$2+AN22*$AN$2+AM22*$AM$2 -> 314 | BB22: 20 | BC22: حسين سالم | DL22: =SUM(BD22:DK22) -> 0 | DM22: 15 | DN22: =DM22-DL22 -> 15 | DO22: =SUM(DP22:FW22) -> 0 | DP22: =BD22*11 -> 0 | DQ22: =BE22*21 -> 0 | DR22: =BF22*12 -> 0 | DS22: =BG22*22 -> 0 | DT22: =BH22*13 -> 0 | DU22: =BI22*23 -> 0 | DV22: =BJ22*14 -> 0 | DW22: =BK22*24 -> 0 | DX22: =BL22*15 -> 0 | DY22: =BM22*25 -> 0 | DZ22: =BN22*16 -> 0 | EA22: =BO22*26 -> 0 | EB22: =BP22*11 -> 0 | EC22: =BQ22*21 -> 0 | ED22: =BR22*12 -> 0 | EE22: =BS22*22 -> 0 | EF22: =BT22*13 -> 0 | EG22: =BU22*23 -> 0 | EH22: =BV22*14 -> 0 | EI22: =BW22*24 -> 0 | EJ22: =BX22*15 -> 0 | EK22: =BY22*25 -> 0 | EL22: =BZ22*16 -> 0 | EM22: =CA22*26 -> 0 | EN22: =CB22*11 -> 0 | EO22: =CC22*21 -> 0 | EP22: =CD22*12 -> 0 | EQ22: =CE22*22 -> 0 | ER22: =CF22*13 -> 0 | ES22: =CG22*23 -> 0 | ET22: =CH22*14 -> 0 | EU22: =CI22*24 -> 0 | EV22: =CJ22*15 -> 0 | EW22: =CK22*25 -> 0 | EX22: =CL22*16 -> 0 | EY22: =CM22*26 -> 0 | EZ22: =CN22*11 -> 0 | FA22: =CO22*21 -> 0 | FB22: =CP22*12 -> 0 | FC22: =CQ22*22 -> 0 | FD22: =CR22*13 -> 0 | FE22: =CS22*23 -> 0 | FF22: =CT22*14 -> 0 | FG22: =CU22*24 -> 0 | FH22: =CV22*15 -> 0 | FI22: =CW22*25 -> 0 | FJ22: =CX22*16 -> 0 | FK22: =CY22*26 -> 0 | FL22: =CZ22*11 -> 0 | FM22: =DA22*21 -> 0 | FN22: =DB22*12 -> 0 | FO22: =DC22*22 -> 0 | FP22: =DD22*13 -> 0 | FQ22: =DE22*23 -> 0 | FR22: =DF22*14 -> 0 | FS22: =DG22*24 -> 0 | FT22: =DH22*15 -> 0 | FU22: =DI22*25 -> 0 | FV22: =DJ22*16 -> 0 | FW22: =DK22*26 -> 0 | FX22: =#REF! -> #REF! | FY22: =FX22-DO22 -> #REF!
A23: =A22+1 -> 21 | B23: حسين الفيفيي | E23: 4 | F23: 4 | M23: 3 | N23: 3 | O23: =SUM(C23:H23) -> 8 | P23: =SUM(I23:N23) -> 6 | Q23: =SUM(C23:N23) -> 14 | S23: =S22+1 -> 21 | T23: =B23 -> حسين الفيفيي | AG23: =SUM(U23:AB23) -> 0 | AH23: =SUM(AA23:AF23) -> 0 | AI23: =AH23+AG23 -> 0 | AJ23: 11 | AK23: =AK22+1 -> 21 | AL23: =B23 -> حسين الفيفيي | AM23: =C23-U23 -> 0 | AN23: =D23-V23 -> 0 | AO23: =E23-W23 -> 4 | AP23: =F23-X23 -> 4 | AQ23: =G23-Y23 -> 0 | AR23: =H23-Z23 -> 0 | AS23: =I23-AA23 -> 0 | AT23: =J23-AB23 -> 0 | ... AX23: =N23-AF23 -> 3 | AY23: =SUM(AM23:AX23) -> 14 | AZ23: =AX23*$AX$2+AW23*$AW$2+AV23*$AV$2+AU23*$AU$2+AT23*$AT$2+AS23*$AS$2+AR23*$AR$2+AQ23*$AQ$2+AP23*$AP$2+AO23*$AO$2+AN23*$AN$2+AM23*$AM$2 -> 262
A24: =A23+1 -> 22 | B24: ابراهيم | C24: 6 | M24: 4 | N24: 4 | O24: =SUM(C24:H24) -> 6 | P24: =SUM(I24:N24) -> 8 | Q24: =SUM(C24:N24) -> 14 | S24: =S23+1 -> 22 | T24: =B24 -> ابراهيم | AG24: =SUM(U24:AB24) -> 0 | AH24: =SUM(AA24:AF24) -> 0 | AI24: =AH24+AG24 -> 0 | AJ24: 12 | AK24: =AK23+1 -> 22 | AL24: =B24 -> ابراهيم | AM24: =C24-U24 -> 6 | AN24: =D24-V24 -> 0 | AO24: =E24-W24 -> 0 | AP24: =F24-X24 -> 0 | AQ24: =G24-Y24 -> 0 | AR24: =H24-Z24 -> 0 | AS24: =I24-AA24 -> 0 | AT24: =J24-AB24 -> 0 | ... AX24: =N24-AF24 -> 4 | AY24: =SUM(AM24:AX24) -> 14 | AZ24: =AX24*$AX$2+AW24*$AW$2+AV24*$AV$2+AU24*$AU$2+AT24*$AT$2+AS24*$AS$2+AR24*$AR$2+AQ24*$AQ$2+AP24*$AP$2+AO24*$AO$2+AN24*$AN$2+AM24*$AM$2 -> 234 | BB24: 21 | BC24: ابراهيم | DL24: =SUM(BD24:DK24) -> 0 | DM24: 18 | DN24: =DM24-DL24 -> 18 | DO24: =SUM(DP24:FW24) -> 0 | DP24: =BD24*11 -> 0 | DQ24: =BE24*21 -> 0 | DR24: =BF24*12 -> 0 | DS24: =BG24*22 -> 0 | DT24: =BH24*13 -> 0 | DU24: =BI24*23 -> 0 | DV24: =BJ24*14 -> 0 | DW24: =BK24*24 -> 0 | DX24: =BL24*15 -> 0 | DY24: =BM24*25 -> 0 | DZ24: =BN24*16 -> 0 | EA24: =BO24*26 -> 0 | EB24: =BP24*11 -> 0 | EC24: =BQ24*21 -> 0 | ED24: =BR24*12 -> 0 | EE24: =BS24*22 -> 0 | EF24: =BT24*13 -> 0 | EG24: =BU24*23 -> 0 | EH24: =BV24*14 -> 0 | EI24: =BW24*24 -> 0 | EJ24: =BX24*15 -> 0 | EK24: =BY24*25 -> 0 | EL24: =BZ24*16 -> 0 | EM24: =CA24*26 -> 0 | EN24: =CB24*11 -> 0 | EO24: =CC24*21 -> 0 | EP24: =CD24*12 -> 0 | EQ24: =CE24*22 -> 0 | ER24: =CF24*13 -> 0 | ES24: =CG24*23 -> 0 | ET24: =CH24*14 -> 0 | EU24: =CI24*24 -> 0 | EV24: =CJ24*15 -> 0 | EW24: =CK24*25 -> 0 | EX24: =CL24*16 -> 0 | EY24: =CM24*26 -> 0 | EZ24: =CN24*11 -> 0 | FA24: =CO24*21 -> 0 | FB24: =CP24*12 -> 0 | FC24: =CQ24*22 -> 0 | FD24: =CR24*13 -> 0 | FE24: =CS24*23 -> 0 | FF24: =CT24*14 -> 0 | FG24: =CU24*24 -> 0 | FH24: =CV24*15 -> 0 | FI24: =CW24*25 -> 0 | FJ24: =CX24*16 -> 0 | FK24: =CY24*26 -> 0 | FL24: =CZ24*11 -> 0 | FM24: =DA24*21 -> 0 | FN24: =DB24*12 -> 0 | FO24: =DC24*22 -> 0 | FP24: =DD24*13 -> 0 | FQ24: =DE24*23 -> 0 | FR24: =DF24*14 -> 0 | FS24: =DG24*24 -> 0 | FT24: =DH24*15 -> 0 | FU24: =DI24*25 -> 0 | FV24: =DJ24*16 -> 0 | FW24: =DK24*26 -> 0 | FX24: =#REF! -> #REF! | FY24: =FX24-DO24 -> #REF!
A25: =A24+1 -> 23 | B25: سلمان محيي | I25: 3 | J25: 3 | K25: 4 | L25: 4 | O25: =SUM(C25:H25) -> 0 | P25: =SUM(I25:N25) -> 14 | Q25: =SUM(C25:N25) -> 14 | S25: =S24+1 -> 23 | T25: =B25 -> سلمان محيي | AG25: =SUM(U25:AB25) -> 0 | AH25: =SUM(AA25:AF25) -> 0 | AI25: =AH25+AG25 -> 0 | AJ25: 13 | AK25: =AK24+1 -> 23 | AL25: =B25 -> سلمان محيي | AM25: =C25-U25 -> 0 | AN25: =D25-V25 -> 0 | AO25: =E25-W25 -> 0 | AP25: =F25-X25 -> 0 | AQ25: =G25-Y25 -> 0 | AR25: =H25-Z25 -> 0 | AS25: =I25-AA25 -> 3 | AT25: =J25-AB25 -> 3 | ... AX25: =N25-AF25 -> 0 | AY25: =SUM(AM25:AX25) -> 14 | AZ25: =AX25*$AX$2+AW25*$AW$2+AV25*$AV$2+AU25*$AU$2+AT25*$AT$2+AS25*$AS$2+AR25*$AR$2+AQ25*$AQ$2+AP25*$AP$2+AO25*$AO$2+AN25*$AN$2+AM25*$AM$2 -> 274
A26: =A25+1 -> 24 | B26: حسين العمري | C26: 4 | M26: 5 | N26: 5 | O26: =SUM(C26:H26) -> 4 | P26: =SUM(I26:N26) -> 10 | Q26: =SUM(C26:N26) -> 14 | S26: =S25+1 -> 24 | T26: =B26 -> حسين العمري | AG26: =SUM(U26:AB26) -> 0 | AH26: =SUM(AA26:AF26) -> 0 | AI26: =AH26+AG26 -> 0 | AJ26: 13 | AK26: =AK25+1 -> 24 | AL26: =B26 -> حسين العمري | AM26: =C26-U26 -> 4 | AN26: =D26-V26 -> 0 | AO26: =E26-W26 -> 0 | AP26: =F26-X26 -> 0 | AQ26: =G26-Y26 -> 0 | AR26: =H26-Z26 -> 0 | AS26: =I26-AA26 -> 0 | AT26: =J26-AB26 -> 0 | ... AX26: =N26-AF26 -> 5 | AY26: =SUM(AM26:AX26) -> 14 | AZ26: =AX26*$AX$2+AW26*$AW$2+AV26*$AV$2+AU26*$AU$2+AT26*$AT$2+AS26*$AS$2+AR26*$AR$2+AQ26*$AQ$2+AP26*$AP$2+AO26*$AO$2+AN26*$AN$2+AM26*$AM$2 -> 254 | BB26: 22 | BC26: احياء | DL26: =SUM(BD26:DK26) -> 0 | DM26: 18 | DN26: =DM26-DL26 -> 18 | DO26: =SUM(DP26:FW26) -> 0 | DP26: =BD26*11 -> 0 | DQ26: =BE26*21 -> 0 | DR26: =BF26*12 -> 0 | DS26: =BG26*22 -> 0 | DT26: =BH26*13 -> 0 | DU26: =BI26*23 -> 0 | DV26: =BJ26*14 -> 0 | DW26: =BK26*24 -> 0 | DX26: =BL26*15 -> 0 | DY26: =BM26*25 -> 0 | DZ26: =BN26*16 -> 0 | EA26: =BO26*26 -> 0 | EB26: =BP26*11 -> 0 | EC26: =BQ26*21 -> 0 | ED26: =BR26*12 -> 0 | EE26: =BS26*22 -> 0 | EF26: =BT26*13 -> 0 | EG26: =BU26*23 -> 0 | EH26: =BV26*14 -> 0 | EI26: =BW26*24 -> 0 | EJ26: =BX26*15 -> 0 | EK26: =BY26*25 -> 0 | EL26: =BZ26*16 -> 0 | EM26: =CA26*26 -> 0 | EN26: =CB26*11 -> 0 | EO26: =CC26*21 -> 0 | EP26: =CD26*12 -> 0 | EQ26: =CE26*22 -> 0 | ER26: =CF26*13 -> 0 | ES26: =CG26*23 -> 0 | ET26: =CH26*14 -> 0 | EU26: =CI26*24 -> 0 | EV26: =CJ26*15 -> 0 | EW26: =CK26*25 -> 0 | EX26: =CL26*16 -> 0 | EY26: =CM26*26 -> 0 | EZ26: =CN26*11 -> 0 | FA26: =CO26*21 -> 0 | FB26: =CP26*12 -> 0 | FC26: =CQ26*22 -> 0 | FD26: =CR26*13 -> 0 | FE26: =CS26*23 -> 0 | FF26: =CT26*14 -> 0 | FG26: =CU26*24 -> 0 | FH26: =CV26*15 -> 0 | FI26: =CW26*25 -> 0 | FJ26: =CX26*16 -> 0 | FK26: =CY26*26 -> 0 | FL26: =CZ26*11 -> 0 | FM26: =DA26*21 -> 0 | FN26: =DB26*12 -> 0 | FO26: =DC26*22 -> 0 | FP26: =DD26*13 -> 0 | FQ26: =DE26*23 -> 0 | FR26: =DF26*14 -> 0 | FS26: =DG26*24 -> 0 | FT26: =DH26*15 -> 0 | FU26: =DI26*25 -> 0 | FV26: =DJ26*16 -> 0 | FW26: =DK26*26 -> 0 | FX26: =#REF! -> #REF! | FY26: =FX26-DO26 -> #REF!
A27: =A26+1 -> 25 | B27: حسن جبار | E27: 4 | F27: 4 | K27: 5 | L27: 5 | O27: =SUM(C27:H27) -> 8 | P27: =SUM(I27:N27) -> 10 | Q27: =SUM(C27:N27) -> 18 | S27: =S26+1 -> 25 | T27: =B27 -> حسن جبار | AG27: =SUM(U27:AB27) -> 0 | AH27: =SUM(AA27:AF27) -> 0 | AI27: =AH27+AG27 -> 0 | AJ27: 14 | AK27: =AK26+1 -> 25 | AL27: =B27 -> حسن جبار | AM27: =C27-U27 -> 0 | AN27: =D27-V27 -> 0 | AO27: =E27-W27 -> 4 | AP27: =F27-X27 -> 4 | AQ27: =G27-Y27 -> 0 | AR27: =H27-Z27 -> 0 | AS27: =I27-AA27 -> 0 | AT27: =J27-AB27 -> 0 | ... AX27: =N27-AF27 -> 0 | AY27: =SUM(AM27:AX27) -> 18 | AZ27: =AX27*$AX$2+AW27*$AW$2+AV27*$AV$2+AU27*$AU$2+AT27*$AT$2+AS27*$AS$2+AR27*$AR$2+AQ27*$AQ$2+AP27*$AP$2+AO27*$AO$2+AN27*$AN$2+AM27*$AM$2 -> 336 | BB27: 23 | BC27: حسين العمري | DL27: =SUM(BD27:DK27) -> 0 | DM27: 13 | DN27: =DM27-DL27 -> 13 | DO27: =SUM(DP27:FW27) -> 0 | DP27: =BD27*11 -> 0 | DQ27: =BE27*21 -> 0 | DR27: =BF27*12 -> 0 | DS27: =BG27*22 -> 0 | DT27: =BH27*13 -> 0 | DU27: =BI27*23 -> 0 | DV27: =BJ27*14 -> 0 | DW27: =BK27*24 -> 0 | DX27: =BL27*15 -> 0 | DY27: =BM27*25 -> 0 | DZ27: =BN27*16 -> 0 | EA27: =BO27*26 -> 0 | EB27: =BP27*11 -> 0 | EC27: =BQ27*21 -> 0 | ED27: =BR27*12 -> 0 | EE27: =BS27*22 -> 0 | EF27: =BT27*13 -> 0 | EG27: =BU27*23 -> 0 | EH27: =BV27*14 -> 0 | EI27: =BW27*24 -> 0 | EJ27: =BX27*15 -> 0 | EK27: =BY27*25 -> 0 | EL27: =BZ27*16 -> 0 | EM27: =CA27*26 -> 0 | EN27: =CB27*11 -> 0 | EO27: =CC27*21 -> 0 | EP27: =CD27*12 -> 0 | EQ27: =CE27*22 -> 0 | ER27: =CF27*13 -> 0 | ES27: =CG27*23 -> 0 | ET27: =CH27*14 -> 0 | EU27: =CI27*24 -> 0 | EV27: =CJ27*15 -> 0 | EW27: =CK27*25 -> 0 | EX27: =CL27*16 -> 0 | EY27: =CM27*26 -> 0 | EZ27: =CN27*11 -> 0 | FA27: =CO27*21 -> 0 | FB27: =CP27*12 -> 0 | FC27: =CQ27*22 -> 0 | FD27: =CR27*13 -> 0 | FE27: =CS27*23 -> 0 | FF27: =CT27*14 -> 0 | FG27: =CU27*24 -> 0 | FH27: =CV27*15 -> 0 | FI27: =CW27*25 -> 0 | FJ27: =CX27*16 -> 0 | FK27: =CY27*26 -> 0 | FL27: =CZ27*11 -> 0 | FM27: =DA27*21 -> 0 | FN27: =DB27*12 -> 0 | FO27: =DC27*22 -> 0 | FP27: =DD27*13 -> 0 | FQ27: =DE27*23 -> 0 | FR27: =DF27*14 -> 0 | FS27: =DG27*24 -> 0 | FT27: =DH27*15 -> 0 | FU27: =DI27*25 -> 0 | FV27: =DJ27*16 -> 0 | FW27: =DK27*26 -> 0 | FX27: =#REF! -> #REF! | FY27: =FX27-DO27 -> #REF!
A28: =A27+1 -> 26 | B28: موسى | G28: 4 | H28: 4 | K28: 2 | L28: 2 | O28: =SUM(C28:H28) -> 8 | P28: =SUM(I28:N28) -> 4 | Q28: =SUM(C28:N28) -> 12 | S28: =S27+1 -> 26 | T28: =B28 -> موسى | AG28: =SUM(U28:AB28) -> 0 | AH28: =SUM(AA28:AF28) -> 0 | AI28: =AH28+AG28 -> 0 | AJ28: 15 | AK28: =AK27+1 -> 26 | AL28: =B28 -> موسى | AM28: =C28-U28 -> 0 | AN28: =D28-V28 -> 0 | AO28: =E28-W28 -> 0 | AP28: =F28-X28 -> 0 | AQ28: =G28-Y28 -> 4 | AR28: =H28-Z28 -> 4 | AS28: =I28-AA28 -> 0 | AT28: =J28-AB28 -> 0 | ... AX28: =N28-AF28 -> 0 | AY28: =SUM(AM28:AX28) -> 12 | AZ28: =AX28*$AX$2+AW28*$AW$2+AV28*$AV$2+AU28*$AU$2+AT28*$AT$2+AS28*$AS$2+AR28*$AR$2+AQ28*$AQ$2+AP28*$AP$2+AO28*$AO$2+AN28*$AN$2+AM28*$AM$2 -> 224 | BB28: 24 | BC28: حسن جبار | DL28: =SUM(BD28:DK28) -> 0 | DM28: 13 | DN28: =DM28-DL28 -> 13 | DO28: =SUM(DP28:FW28) -> 0 | DP28: =BD28*11 -> 0 | DQ28: =BE28*21 -> 0 | DR28: =BF28*12 -> 0 | DS28: =BG28*22 -> 0 | DT28: =BH28*13 -> 0 | DU28: =BI28*23 -> 0 | DV28: =BJ28*14 -> 0 | DW28: =BK28*24 -> 0 | DX28: =BL28*15 -> 0 | DY28: =BM28*25 -> 0 | DZ28: =BN28*16 -> 0 | EA28: =BO28*26 -> 0 | EB28: =BP28*11 -> 0 | EC28: =BQ28*21 -> 0 | ED28: =BR28*12 -> 0 | EE28: =BS28*22 -> 0 | EF28: =BT28*13 -> 0 | EG28: =BU28*23 -> 0 | EH28: =BV28*14 -> 0 | EI28: =BW28*24 -> 0 | EJ28: =BX28*15 -> 0 | EK28: =BY28*25 -> 0 | EL28: =BZ28*16 -> 0 | EM28: =CA28*26 -> 0 | EN28: =CB28*11 -> 0 | EO28: =CC28*21 -> 0 | EP28: =CD28*12 -> 0 | EQ28: =CE28*22 -> 0 | ER28: =CF28*13 -> 0 | ES28: =CG28*23 -> 0 | ET28: =CH28*14 -> 0 | EU28: =CI28*24 -> 0 | EV28: =CJ28*15 -> 0 | EW28: =CK28*25 -> 0 | EX28: =CL28*16 -> 0 | EY28: =CM28*26 -> 0 | EZ28: =CN28*11 -> 0 | FA28: =CO28*21 -> 0 | FB28: =CP28*12 -> 0 | FC28: =CQ28*22 -> 0 | FD28: =CR28*13 -> 0 | FE28: =CS28*23 -> 0 | FF28: =CT28*14 -> 0 | FG28: =CU28*24 -> 0 | FH28: =CV28*15 -> 0 | FI28: =CW28*25 -> 0 | FJ28: =CX28*16 -> 0 | FK28: =CY28*26 -> 0 | FL28: =CZ28*11 -> 0 | FM28: =DA28*21 -> 0 | FN28: =DB28*12 -> 0 | FO28: =DC28*22 -> 0 | FP28: =DD28*13 -> 0 | FQ28: =DE28*23 -> 0 | FR28: =DF28*14 -> 0 | FS28: =DG28*24 -> 0 | FT28: =DH28*15 -> 0 | FU28: =DI28*25 -> 0 | FV28: =DJ28*16 -> 0 | FW28: =DK28*26 -> 0 | FX28: =#REF! -> #REF! | FY28: =FX28-DO28 -> #REF!
A29: =A28+1 -> 27 | B29: مهدي | G29: 2 | H29: 2 | K29: 3 | L29: 3 | O29: =SUM(C29:H29) -> 4 | P29: =SUM(I29:N29) -> 6 | Q29: =SUM(C29:N29) -> 10 | S29: =S28+1 -> 27 | T29: =B29 -> مهدي | AG29: =SUM(U29:AB29) -> 0 | AH29: =SUM(AA29:AF29) -> 0 | AI29: =AH29+AG29 -> 0 | AJ29: 16 | AK29: =AK28+1 -> 27 | AL29: =B29 -> مهدي | AM29: =C29-U29 -> 0 | AN29: =D29-V29 -> 0 | AO29: =E29-W29 -> 0 | AP29: =F29-X29 -> 0 | AQ29: =G29-Y29 -> 2 | AR29: =H29-Z29 -> 2 | AS29: =I29-AA29 -> 0 | AT29: =J29-AB29 -> 0 | ... AX29: =N29-AF29 -> 0 | AY29: =SUM(AM29:AX29) -> 10 | AZ29: =AX29*$AX$2+AW29*$AW$2+AV29*$AV$2+AU29*$AU$2+AT29*$AT$2+AS29*$AS$2+AR29*$AR$2+AQ29*$AQ$2+AP29*$AP$2+AO29*$AO$2+AN29*$AN$2+AM29*$AM$2 -> 192 | BB29: 25 | BC29: حسن سليمان | DL29: =SUM(BD29:DK29) -> 0 | DM29: 10 | DN29: =DM29-DL29 -> 10 | DO29: =SUM(DP29:FW29) -> 0 | DP29: =BD29*11 -> 0 | DQ29: =BE29*21 -> 0 | DR29: =BF29*12 -> 0 | DS29: =BG29*22 -> 0 | DT29: =BH29*13 -> 0 | DU29: =BI29*23 -> 0 | DV29: =BJ29*14 -> 0 | DW29: =BK29*24 -> 0 | DX29: =BL29*15 -> 0 | DY29: =BM29*25 -> 0 | DZ29: =BN29*16 -> 0 | EA29: =BO29*26 -> 0 | EB29: =BP29*11 -> 0 | EC29: =BQ29*21 -> 0 | ED29: =BR29*12 -> 0 | EE29: =BS29*22 -> 0 | EF29: =BT29*13 -> 0 | EG29: =BU29*23 -> 0 | EH29: =BV29*14 -> 0 | EI29: =BW29*24 -> 0 | EJ29: =BX29*15 -> 0 | EK29: =BY29*25 -> 0 | EL29: =BZ29*16 -> 0 | EM29: =CA29*26 -> 0 | EN29: =CB29*11 -> 0 | EO29: =CC29*21 -> 0 | EP29: =CD29*12 -> 0 | EQ29: =CE29*22 -> 0 | ER29: =CF29*13 -> 0 | ES29: =CG29*23 -> 0 | ET29: =CH29*14 -> 0 | EU29: =CI29*24 -> 0 | EV29: =CJ29*15 -> 0 | EW29: =CK29*25 -> 0 | EX29: =CL29*16 -> 0 | EY29: =CM29*26 -> 0 | EZ29: =CN29*11 -> 0 | FA29: =CO29*21 -> 0 | FB29: =CP29*12 -> 0 | FC29: =CQ29*22 -> 0 | FD29: =CR29*13 -> 0 | FE29: =CS29*23 -> 0 | FF29: =CT29*14 -> 0 | FG29: =CU29*24 -> 0 | FH29: =CV29*15 -> 0 | FI29: =CW29*25 -> 0 | FJ29: =CX29*16 -> 0 | FK29: =CY29*26 -> 0 | FL29: =CZ29*11 -> 0 | FM29: =DA29*21 -> 0 | FN29: =DB29*12 -> 0 | FO29: =DC29*22 -> 0 | FP29: =DD29*13 -> 0 | FQ29: =DE29*23 -> 0 | FR29: =DF29*14 -> 0 | FS29: =DG29*24 -> 0 | FT29: =DH29*15 -> 0 | FU29: =DI29*25 -> 0 | FV29: =DJ29*16 -> 0 | FW29: =DK29*26 -> 0 | FX29: =#REF! -> #REF! | FY29: =FX29-DO29 -> #REF!
A30: =A29+1 -> 28 | B30: ناصر | H30: 6 | K30: 5 | L30: 5 | O30: =SUM(C30:H30) -> 6 | P30: =SUM(I30:N30) -> 10 | Q30: =SUM(C30:N30) -> 16 | S30: =S29+1 -> 28 | T30: =B30 -> ناصر | AG30: =SUM(U30:AB30) -> 0 | AH30: =SUM(AA30:AF30) -> 0 | AI30: =AH30+AG30 -> 0 | AJ30: 17 | AK30: =AK29+1 -> 28 | AL30: =B30 -> ناصر | AM30: =C30-U30 -> 0 | AN30: =D30-V30 -> 0 | AO30: =E30-W30 -> 0 | AP30: =F30-X30 -> 0 | AQ30: =G30-Y30 -> 0 | AR30: =H30-Z30 -> 6 | AS30: =I30-AA30 -> 0 | AT30: =J30-AB30 -> 0 | ... AX30: =N30-AF30 -> 0 | AY30: =SUM(AM30:AX30) -> 16 | AZ30: =AX30*$AX$2+AW30*$AW$2+AV30*$AV$2+AU30*$AU$2+AT30*$AT$2+AS30*$AS$2+AR30*$AR$2+AQ30*$AQ$2+AP30*$AP$2+AO30*$AO$2+AN30*$AN$2+AM30*$AM$2 -> 338 | BB30: 26 | BC30: مهدي | DL30: =SUM(BD30:DK30) -> 0 | DM30: 2 | DN30: =DM30-DL30 -> 2 | DO30: =SUM(DP30:FW30) -> 0 | DP30: =BD30*11 -> 0 | DQ30: =BE30*21 -> 0 | DR30: =BF30*12 -> 0 | DS30: =BG30*22 -> 0 | DT30: =BH30*13 -> 0 | DU30: =BI30*23 -> 0 | DV30: =BJ30*14 -> 0 | DW30: =BK30*24 -> 0 | DX30: =BL30*15 -> 0 | DY30: =BM30*25 -> 0 | DZ30: =BN30*16 -> 0 | EA30: =BO30*26 -> 0 | EB30: =BP30*11 -> 0 | EC30: =BQ30*21 -> 0 | ED30: =BR30*12 -> 0 | EE30: =BS30*22 -> 0 | EF30: =BT30*13 -> 0 | EG30: =BU30*23 -> 0 | EH30: =BV30*14 -> 0 | EI30: =BW30*24 -> 0 | EJ30: =BX30*15 -> 0 | EK30: =BY30*25 -> 0 | EL30: =BZ30*16 -> 0 | EM30: =CA30*26 -> 0 | EN30: =CB30*11 -> 0 | EO30: =CC30*21 -> 0 | EP30: =CD30*12 -> 0 | EQ30: =CE30*22 -> 0 | ER30: =CF30*13 -> 0 | ES30: =CG30*23 -> 0 | ET30: =CH30*14 -> 0 | EU30: =CI30*24 -> 0 | EV30: =CJ30*15 -> 0 | EW30: =CK30*25 -> 0 | EX30: =CL30*16 -> 0 | EY30: =CM30*26 -> 0 | EZ30: =CN30*11 -> 0 | FA30: =CO30*21 -> 0 | FB30: =CP30*12 -> 0 | FC30: =CQ30*22 -> 0 | FD30: =CR30*13 -> 0 | FE30: =CS30*23 -> 0 | FF30: =CT30*14 -> 0 | FG30: =CU30*24 -> 0 | FH30: =CV30*15 -> 0 | FI30: =CW30*25 -> 0 | FJ30: =CX30*16 -> 0 | FK30: =CY30*26 -> 0 | FL30: =CZ30*11 -> 0 | FM30: =DA30*21 -> 0 | FN30: =DB30*12 -> 0 | FO30: =DC30*22 -> 0 | FP30: =DD30*13 -> 0 | FQ30: =DE30*23 -> 0 | FR30: =DF30*14 -> 0 | FS30: =DG30*24 -> 0 | FT30: =DH30*15 -> 0 | FU30: =DI30*25 -> 0 | FV30: =DJ30*16 -> 0 | FW30: =DK30*26 -> 0 | FX30: =#REF! -> #REF! | FY30: =FX30-DO30 -> #REF!
A31: =A30+1 -> 29 | B31: خالد الخالدي | M31: 8 | N31: 8 | O31: =SUM(C31:H31) -> 0 | P31: =SUM(I31:N31) -> 16 | Q31: =SUM(C31:N31) -> 16 | S31: =S30+1 -> 29 | T31: =B31 -> خالد الخالدي | AG31: =SUM(U31:AB31) -> 0 | AH31: =SUM(AA31:AF31) -> 0 | AI31: =AH31+AG31 -> 0 | AJ31: 18 | AK31: =AK30+1 -> 29 | AL31: =B31 -> خالد الخالدي | AM31: =C31-U31 -> 0 | AN31: =D31-V31 -> 0 | AO31: =E31-W31 -> 0 | AP31: =F31-X31 -> 0 | AQ31: =G31-Y31 -> 0 | AR31: =H31-Z31 -> 0 | AS31: =I31-AA31 -> 0 | AT31: =J31-AB31 -> 0 | ... AX31: =N31-AF31 -> 8 | AY31: =SUM(AM31:AX31) -> 16 | AZ31: =AX31*$AX$2+AW31*$AW$2+AV31*$AV$2+AU31*$AU$2+AT31*$AT$2+AS31*$AS$2+AR31*$AR$2+AQ31*$AQ$2+AP31*$AP$2+AO31*$AO$2+AN31*$AN$2+AM31*$AM$2 -> 336
A32: المجموع | C32: =SUM(C3:C31) -> 35 | D32: =SUM(D3:D31) -> 0 | E32: =SUM(E3:E31) -> 35 | F32: =SUM(F3:F31) -> 35 | G32: =SUM(G3:G31) -> 35 | H32: =SUM(H3:H31) -> 35 | I32: =SUM(I3:I31) -> 32 | J32: =SUM(J3:J31) -> 32 | ... P32: =SUM(P3:P31) -> 192 | S32: المجموع | U32: =SUM(U3:U31) -> 0 | V32: =SUM(V3:V31) -> 0 | W32: =SUM(W3:W31) -> 0 | X32: =SUM(X3:X31) -> 0 | Y32: =SUM(Y3:Y31) -> 0 | Z32: =SUM(Z3:Z31) -> 0 | AA32: =SUM(AA3:AA31) -> 0 | AB32: =SUM(AB3:AB31) -> 0 | ... AH32: =SUM(AH3:AH31) -> 0 | AI32: =AH32+AG32 -> 0 | AK32: المجموع | AM32: =C32-U32 -> 35 | AN32: =D32-V32 -> 0 | AO32: =E32-W32 -> 35 | AP32: =F32-X32 -> 35 | AQ32: =G32-Y32 -> 35 | AR32: =H32-Z32 -> 35 | AS32: =I32-AA32 -> 32 | AT32: =J32-AB32 -> 32 | ... AX32: =N32-AF32 -> 32 | BD32: =SUM(BD3:BD30) -> 1 | BE32: =SUM(BE3:BE30) -> 1 | BF32: =SUM(BF3:BF30) -> 0 | BG32: =SUM(BG3:BG30) -> 0 | BH32: =SUM(BH3:BH30) -> 0 | BI32: =SUM(BI3:BI30) -> 0 | BJ32: =SUM(BJ3:BJ30) -> 0 | BK32: =SUM(BK3:BK30) -> 0 | ... DK32: =SUM(DK3:DK30) -> 0 | DL32: =SUM(BD32:DK32) -> 19
Q33: =SUM(Q3:Q32) -> 367 | AY33: =SUM(AY3:AY32) -> 367 | BD33: =6-BD32 -> 5 | BE33: =6-BE32 -> 5 | BF33: =6-BF32 -> 6 | BG33: =6-BG32 -> 6 | BH33: =6-BH32 -> 6 | BI33: =6-BI32 -> 6 | BJ33: =6-BJ32 -> 6 | BK33: =6-BK32 -> 6 | ... DK33: =6-DK32 -> 6

Sheet الفصول
A2: 11 | B2: =CONCATENATE(D2," ",E2," ",F2) -> 1 م | D2: 1 | E2: م
A3: 21 | B3: =CONCATENATE(D3," ",E3," ",F3) -> 1 م ب | D3: 1 | E3: م | F3: ب
A4: 12 | B4: =CONCATENATE(D4," ",E4," ",F4) -> 2 م أ | D4: 2 | E4: م | F4: أ
A5: 22 | B5: =CONCATENATE(D5," ",E5," ",F5) -> 2 م ب | D5: 2 | E5: م | F5: ب
